WARNING 2019-06-12 08:59:59,350 base 152 Not Found: /
WARNING 2019-06-12 08:59:59,350 basehttp 124 "GET / HTTP/1.1" 404 2070
WARNING 2019-06-12 08:59:59,355 base 152 Not Found: /
WARNING 2019-06-12 08:59:59,355 basehttp 124 "GET / HTTP/1.1" 404 2070
WARNING 2019-06-12 08:59:59,442 base 152 Not Found: /favicon.ico
WARNING 2019-06-12 08:59:59,442 basehttp 124 "GET /favicon.ico HTTP/1.1" 404 2121
WARNING 2019-06-12 09:00:08,731 base 152 Not Found: /registration/
WARNING 2019-06-12 09:00:08,732 basehttp 124 "GET /registration/ HTTP/1.1" 404 2127
INFO 2019-06-12 09:00:24,178 basehttp 124 "GET /register HTTP/1.1" 301 0
ERROR 2019-06-12 09:00:24,182 exception 135 Internal Server Error: /register/
Traceback (most recent call last):
  File "/home/lsy/.virtualenvs/py3_django/lib/python3.5/site-packages/django/template/utils.py", line 65, in __getitem__
    return self._engines[alias]
KeyError: 'jinja2'

During handling of the above exception, another exception occurred:

Traceback (most recent call last):
  File "/home/lsy/.virtualenvs/py3_django/lib/python3.5/site-packages/django/core/handlers/exception.py", line 41, in inner
    response = get_response(request)
  File "/home/lsy/.virtualenvs/py3_django/lib/python3.5/site-packages/django/core/handlers/base.py", line 187, in _get_response
    response = self.process_exception_by_middleware(e, request)
  File "/home/lsy/.virtualenvs/py3_django/lib/python3.5/site-packages/django/core/handlers/base.py", line 185, in _get_response
    response = wrapped_callback(request, *callback_args, **callback_kwargs)
  File "/home/lsy/.virtualenvs/py3_django/lib/python3.5/site-packages/django/views/generic/base.py", line 68, in view
    return self.dispatch(request, *args, **kwargs)
  File "/home/lsy/.virtualenvs/py3_django/lib/python3.5/site-packages/django/views/generic/base.py", line 88, in dispatch
    return handler(request, *args, **kwargs)
  File "/home/lsy/Desktop/project/meiduo/apps/users/views.py", line 10, in get
    return render(request, 'register.html')
  File "/home/lsy/.virtualenvs/py3_django/lib/python3.5/site-packages/django/shortcuts.py", line 30, in render
    content = loader.render_to_string(template_name, context, request, using=using)
  File "/home/lsy/.virtualenvs/py3_django/lib/python3.5/site-packages/django/template/loader.py", line 67, in render_to_string
    template = get_template(template_name, using=using)
  File "/home/lsy/.virtualenvs/py3_django/lib/python3.5/site-packages/django/template/loader.py", line 18, in get_template
    engines = _engine_list(using)
  File "/home/lsy/.virtualenvs/py3_django/lib/python3.5/site-packages/django/template/loader.py", line 72, in _engine_list
    return engines.all() if using is None else [engines[using]]
  File "/home/lsy/.virtualenvs/py3_django/lib/python3.5/site-packages/django/template/utils.py", line 89, in all
    return [self[alias] for alias in self]
  File "/home/lsy/.virtualenvs/py3_django/lib/python3.5/site-packages/django/template/utils.py", line 89, in <listcomp>
    return [self[alias] for alias in self]
  File "/home/lsy/.virtualenvs/py3_django/lib/python3.5/site-packages/django/template/utils.py", line 80, in __getitem__
    engine = engine_cls(params)
  File "/home/lsy/.virtualenvs/py3_django/lib/python3.5/site-packages/django/template/backends/jinja2.py", line 29, in __init__
    environment_cls = import_string(environment)
  File "/home/lsy/.virtualenvs/py3_django/lib/python3.5/site-packages/django/utils/module_loading.py", line 20, in import_string
    module = import_module(module_path)
  File "/home/lsy/.virtualenvs/py3_django/lib/python3.5/importlib/__init__.py", line 126, in import_module
    return _bootstrap._gcd_import(name[level:], package, level)
  File "<frozen importlib._bootstrap>", line 986, in _gcd_import
  File "<frozen importlib._bootstrap>", line 969, in _find_and_load
  File "<frozen importlib._bootstrap>", line 956, in _find_and_load_unlocked
ImportError: No module named 'utils.jinja2_env'
ERROR 2019-06-12 09:00:24,231 basehttp 124 "GET /register/ HTTP/1.1" 500 126617
ERROR 2019-06-12 09:00:53,637 exception 135 Internal Server Error: /register/
Traceback (most recent call last):
  File "/home/lsy/.virtualenvs/py3_django/lib/python3.5/site-packages/django/template/utils.py", line 65, in __getitem__
    return self._engines[alias]
KeyError: 'jinja2'

During handling of the above exception, another exception occurred:

Traceback (most recent call last):
  File "/home/lsy/.virtualenvs/py3_django/lib/python3.5/site-packages/django/core/handlers/exception.py", line 41, in inner
    response = get_response(request)
  File "/home/lsy/.virtualenvs/py3_django/lib/python3.5/site-packages/django/core/handlers/base.py", line 187, in _get_response
    response = self.process_exception_by_middleware(e, request)
  File "/home/lsy/.virtualenvs/py3_django/lib/python3.5/site-packages/django/core/handlers/base.py", line 185, in _get_response
    response = wrapped_callback(request, *callback_args, **callback_kwargs)
  File "/home/lsy/.virtualenvs/py3_django/lib/python3.5/site-packages/django/views/generic/base.py", line 68, in view
    return self.dispatch(request, *args, **kwargs)
  File "/home/lsy/.virtualenvs/py3_django/lib/python3.5/site-packages/django/views/generic/base.py", line 88, in dispatch
    return handler(request, *args, **kwargs)
  File "/home/lsy/Desktop/project/meiduo/apps/users/views.py", line 10, in get
    return render(request, 'register.html')
  File "/home/lsy/.virtualenvs/py3_django/lib/python3.5/site-packages/django/shortcuts.py", line 30, in render
    content = loader.render_to_string(template_name, context, request, using=using)
  File "/home/lsy/.virtualenvs/py3_django/lib/python3.5/site-packages/django/template/loader.py", line 67, in render_to_string
    template = get_template(template_name, using=using)
  File "/home/lsy/.virtualenvs/py3_django/lib/python3.5/site-packages/django/template/loader.py", line 18, in get_template
    engines = _engine_list(using)
  File "/home/lsy/.virtualenvs/py3_django/lib/python3.5/site-packages/django/template/loader.py", line 72, in _engine_list
    return engines.all() if using is None else [engines[using]]
  File "/home/lsy/.virtualenvs/py3_django/lib/python3.5/site-packages/django/template/utils.py", line 89, in all
    return [self[alias] for alias in self]
  File "/home/lsy/.virtualenvs/py3_django/lib/python3.5/site-packages/django/template/utils.py", line 89, in <listcomp>
    return [self[alias] for alias in self]
  File "/home/lsy/.virtualenvs/py3_django/lib/python3.5/site-packages/django/template/utils.py", line 80, in __getitem__
    engine = engine_cls(params)
  File "/home/lsy/.virtualenvs/py3_django/lib/python3.5/site-packages/django/template/backends/jinja2.py", line 29, in __init__
    environment_cls = import_string(environment)
  File "/home/lsy/.virtualenvs/py3_django/lib/python3.5/site-packages/django/utils/module_loading.py", line 20, in import_string
    module = import_module(module_path)
  File "/home/lsy/.virtualenvs/py3_django/lib/python3.5/importlib/__init__.py", line 126, in import_module
    return _bootstrap._gcd_import(name[level:], package, level)
  File "<frozen importlib._bootstrap>", line 986, in _gcd_import
  File "<frozen importlib._bootstrap>", line 969, in _find_and_load
  File "<frozen importlib._bootstrap>", line 956, in _find_and_load_unlocked
ImportError: No module named 'utils.jinja2_env'
ERROR 2019-06-12 09:00:53,683 basehttp 124 "GET /register/ HTTP/1.1" 500 126752
ERROR 2019-06-12 09:00:55,586 exception 135 Internal Server Error: /register/
Traceback (most recent call last):
  File "/home/lsy/.virtualenvs/py3_django/lib/python3.5/site-packages/django/template/utils.py", line 65, in __getitem__
    return self._engines[alias]
KeyError: 'jinja2'

During handling of the above exception, another exception occurred:

Traceback (most recent call last):
  File "/home/lsy/.virtualenvs/py3_django/lib/python3.5/site-packages/django/core/handlers/exception.py", line 41, in inner
    response = get_response(request)
  File "/home/lsy/.virtualenvs/py3_django/lib/python3.5/site-packages/django/core/handlers/base.py", line 187, in _get_response
    response = self.process_exception_by_middleware(e, request)
  File "/home/lsy/.virtualenvs/py3_django/lib/python3.5/site-packages/django/core/handlers/base.py", line 185, in _get_response
    response = wrapped_callback(request, *callback_args, **callback_kwargs)
  File "/home/lsy/.virtualenvs/py3_django/lib/python3.5/site-packages/django/views/generic/base.py", line 68, in view
    return self.dispatch(request, *args, **kwargs)
  File "/home/lsy/.virtualenvs/py3_django/lib/python3.5/site-packages/django/views/generic/base.py", line 88, in dispatch
    return handler(request, *args, **kwargs)
  File "/home/lsy/Desktop/project/meiduo/apps/users/views.py", line 10, in get
    return render(request, 'register.html')
  File "/home/lsy/.virtualenvs/py3_django/lib/python3.5/site-packages/django/shortcuts.py", line 30, in render
    content = loader.render_to_string(template_name, context, request, using=using)
  File "/home/lsy/.virtualenvs/py3_django/lib/python3.5/site-packages/django/template/loader.py", line 67, in render_to_string
    template = get_template(template_name, using=using)
  File "/home/lsy/.virtualenvs/py3_django/lib/python3.5/site-packages/django/template/loader.py", line 18, in get_template
    engines = _engine_list(using)
  File "/home/lsy/.virtualenvs/py3_django/lib/python3.5/site-packages/django/template/loader.py", line 72, in _engine_list
    return engines.all() if using is None else [engines[using]]
  File "/home/lsy/.virtualenvs/py3_django/lib/python3.5/site-packages/django/template/utils.py", line 89, in all
    return [self[alias] for alias in self]
  File "/home/lsy/.virtualenvs/py3_django/lib/python3.5/site-packages/django/template/utils.py", line 89, in <listcomp>
    return [self[alias] for alias in self]
  File "/home/lsy/.virtualenvs/py3_django/lib/python3.5/site-packages/django/template/utils.py", line 80, in __getitem__
    engine = engine_cls(params)
  File "/home/lsy/.virtualenvs/py3_django/lib/python3.5/site-packages/django/template/backends/jinja2.py", line 29, in __init__
    environment_cls = import_string(environment)
  File "/home/lsy/.virtualenvs/py3_django/lib/python3.5/site-packages/django/utils/module_loading.py", line 20, in import_string
    module = import_module(module_path)
  File "/home/lsy/.virtualenvs/py3_django/lib/python3.5/importlib/__init__.py", line 126, in import_module
    return _bootstrap._gcd_import(name[level:], package, level)
  File "<frozen importlib._bootstrap>", line 986, in _gcd_import
  File "<frozen importlib._bootstrap>", line 969, in _find_and_load
  File "<frozen importlib._bootstrap>", line 956, in _find_and_load_unlocked
ImportError: No module named 'utils.jinja2_env'
ERROR 2019-06-12 09:00:55,630 basehttp 124 "GET /register/ HTTP/1.1" 500 126752
ERROR 2019-06-12 09:01:49,672 exception 135 Internal Server Error: /register/
Traceback (most recent call last):
  File "/home/lsy/.virtualenvs/py3_django/lib/python3.5/site-packages/django/template/utils.py", line 65, in __getitem__
    return self._engines[alias]
KeyError: 'jinja2'

During handling of the above exception, another exception occurred:

Traceback (most recent call last):
  File "/home/lsy/.virtualenvs/py3_django/lib/python3.5/site-packages/django/core/handlers/exception.py", line 41, in inner
    response = get_response(request)
  File "/home/lsy/.virtualenvs/py3_django/lib/python3.5/site-packages/django/core/handlers/base.py", line 187, in _get_response
    response = self.process_exception_by_middleware(e, request)
  File "/home/lsy/.virtualenvs/py3_django/lib/python3.5/site-packages/django/core/handlers/base.py", line 185, in _get_response
    response = wrapped_callback(request, *callback_args, **callback_kwargs)
  File "/home/lsy/.virtualenvs/py3_django/lib/python3.5/site-packages/django/views/generic/base.py", line 68, in view
    return self.dispatch(request, *args, **kwargs)
  File "/home/lsy/.virtualenvs/py3_django/lib/python3.5/site-packages/django/views/generic/base.py", line 88, in dispatch
    return handler(request, *args, **kwargs)
  File "/home/lsy/Desktop/project/meiduo/apps/users/views.py", line 10, in get
    return render(request, 'register.html')
  File "/home/lsy/.virtualenvs/py3_django/lib/python3.5/site-packages/django/shortcuts.py", line 30, in render
    content = loader.render_to_string(template_name, context, request, using=using)
  File "/home/lsy/.virtualenvs/py3_django/lib/python3.5/site-packages/django/template/loader.py", line 67, in render_to_string
    template = get_template(template_name, using=using)
  File "/home/lsy/.virtualenvs/py3_django/lib/python3.5/site-packages/django/template/loader.py", line 18, in get_template
    engines = _engine_list(using)
  File "/home/lsy/.virtualenvs/py3_django/lib/python3.5/site-packages/django/template/loader.py", line 72, in _engine_list
    return engines.all() if using is None else [engines[using]]
  File "/home/lsy/.virtualenvs/py3_django/lib/python3.5/site-packages/django/template/utils.py", line 89, in all
    return [self[alias] for alias in self]
  File "/home/lsy/.virtualenvs/py3_django/lib/python3.5/site-packages/django/template/utils.py", line 89, in <listcomp>
    return [self[alias] for alias in self]
  File "/home/lsy/.virtualenvs/py3_django/lib/python3.5/site-packages/django/template/utils.py", line 80, in __getitem__
    engine = engine_cls(params)
  File "/home/lsy/.virtualenvs/py3_django/lib/python3.5/site-packages/django/template/backends/jinja2.py", line 29, in __init__
    environment_cls = import_string(environment)
  File "/home/lsy/.virtualenvs/py3_django/lib/python3.5/site-packages/django/utils/module_loading.py", line 20, in import_string
    module = import_module(module_path)
  File "/home/lsy/.virtualenvs/py3_django/lib/python3.5/importlib/__init__.py", line 126, in import_module
    return _bootstrap._gcd_import(name[level:], package, level)
  File "<frozen importlib._bootstrap>", line 986, in _gcd_import
  File "<frozen importlib._bootstrap>", line 969, in _find_and_load
  File "<frozen importlib._bootstrap>", line 956, in _find_and_load_unlocked
ImportError: No module named 'utils.jinja2_env'
ERROR 2019-06-12 09:01:49,716 basehttp 124 "GET /register/ HTTP/1.1" 500 126752
ERROR 2019-06-12 09:01:50,768 exception 135 Internal Server Error: /register/
Traceback (most recent call last):
  File "/home/lsy/.virtualenvs/py3_django/lib/python3.5/site-packages/django/template/utils.py", line 65, in __getitem__
    return self._engines[alias]
KeyError: 'jinja2'

During handling of the above exception, another exception occurred:

Traceback (most recent call last):
  File "/home/lsy/.virtualenvs/py3_django/lib/python3.5/site-packages/django/core/handlers/exception.py", line 41, in inner
    response = get_response(request)
  File "/home/lsy/.virtualenvs/py3_django/lib/python3.5/site-packages/django/core/handlers/base.py", line 187, in _get_response
    response = self.process_exception_by_middleware(e, request)
  File "/home/lsy/.virtualenvs/py3_django/lib/python3.5/site-packages/django/core/handlers/base.py", line 185, in _get_response
    response = wrapped_callback(request, *callback_args, **callback_kwargs)
  File "/home/lsy/.virtualenvs/py3_django/lib/python3.5/site-packages/django/views/generic/base.py", line 68, in view
    return self.dispatch(request, *args, **kwargs)
  File "/home/lsy/.virtualenvs/py3_django/lib/python3.5/site-packages/django/views/generic/base.py", line 88, in dispatch
    return handler(request, *args, **kwargs)
  File "/home/lsy/Desktop/project/meiduo/apps/users/views.py", line 10, in get
    return render(request, 'register.html')
  File "/home/lsy/.virtualenvs/py3_django/lib/python3.5/site-packages/django/shortcuts.py", line 30, in render
    content = loader.render_to_string(template_name, context, request, using=using)
  File "/home/lsy/.virtualenvs/py3_django/lib/python3.5/site-packages/django/template/loader.py", line 67, in render_to_string
    template = get_template(template_name, using=using)
  File "/home/lsy/.virtualenvs/py3_django/lib/python3.5/site-packages/django/template/loader.py", line 18, in get_template
    engines = _engine_list(using)
  File "/home/lsy/.virtualenvs/py3_django/lib/python3.5/site-packages/django/template/loader.py", line 72, in _engine_list
    return engines.all() if using is None else [engines[using]]
  File "/home/lsy/.virtualenvs/py3_django/lib/python3.5/site-packages/django/template/utils.py", line 89, in all
    return [self[alias] for alias in self]
  File "/home/lsy/.virtualenvs/py3_django/lib/python3.5/site-packages/django/template/utils.py", line 89, in <listcomp>
    return [self[alias] for alias in self]
  File "/home/lsy/.virtualenvs/py3_django/lib/python3.5/site-packages/django/template/utils.py", line 80, in __getitem__
    engine = engine_cls(params)
  File "/home/lsy/.virtualenvs/py3_django/lib/python3.5/site-packages/django/template/backends/jinja2.py", line 29, in __init__
    environment_cls = import_string(environment)
  File "/home/lsy/.virtualenvs/py3_django/lib/python3.5/site-packages/django/utils/module_loading.py", line 20, in import_string
    module = import_module(module_path)
  File "/home/lsy/.virtualenvs/py3_django/lib/python3.5/importlib/__init__.py", line 126, in import_module
    return _bootstrap._gcd_import(name[level:], package, level)
  File "<frozen importlib._bootstrap>", line 986, in _gcd_import
  File "<frozen importlib._bootstrap>", line 969, in _find_and_load
  File "<frozen importlib._bootstrap>", line 956, in _find_and_load_unlocked
ImportError: No module named 'utils.jinja2_env'
ERROR 2019-06-12 09:01:50,813 basehttp 124 "GET /register/ HTTP/1.1" 500 126752
ERROR 2019-06-12 09:01:51,902 exception 135 Internal Server Error: /register/
Traceback (most recent call last):
  File "/home/lsy/.virtualenvs/py3_django/lib/python3.5/site-packages/django/template/utils.py", line 65, in __getitem__
    return self._engines[alias]
KeyError: 'jinja2'

During handling of the above exception, another exception occurred:

Traceback (most recent call last):
  File "/home/lsy/.virtualenvs/py3_django/lib/python3.5/site-packages/django/core/handlers/exception.py", line 41, in inner
    response = get_response(request)
  File "/home/lsy/.virtualenvs/py3_django/lib/python3.5/site-packages/django/core/handlers/base.py", line 187, in _get_response
    response = self.process_exception_by_middleware(e, request)
  File "/home/lsy/.virtualenvs/py3_django/lib/python3.5/site-packages/django/core/handlers/base.py", line 185, in _get_response
    response = wrapped_callback(request, *callback_args, **callback_kwargs)
  File "/home/lsy/.virtualenvs/py3_django/lib/python3.5/site-packages/django/views/generic/base.py", line 68, in view
    return self.dispatch(request, *args, **kwargs)
  File "/home/lsy/.virtualenvs/py3_django/lib/python3.5/site-packages/django/views/generic/base.py", line 88, in dispatch
    return handler(request, *args, **kwargs)
  File "/home/lsy/Desktop/project/meiduo/apps/users/views.py", line 10, in get
    return render(request, 'register.html')
  File "/home/lsy/.virtualenvs/py3_django/lib/python3.5/site-packages/django/shortcuts.py", line 30, in render
    content = loader.render_to_string(template_name, context, request, using=using)
  File "/home/lsy/.virtualenvs/py3_django/lib/python3.5/site-packages/django/template/loader.py", line 67, in render_to_string
    template = get_template(template_name, using=using)
  File "/home/lsy/.virtualenvs/py3_django/lib/python3.5/site-packages/django/template/loader.py", line 18, in get_template
    engines = _engine_list(using)
  File "/home/lsy/.virtualenvs/py3_django/lib/python3.5/site-packages/django/template/loader.py", line 72, in _engine_list
    return engines.all() if using is None else [engines[using]]
  File "/home/lsy/.virtualenvs/py3_django/lib/python3.5/site-packages/django/template/utils.py", line 89, in all
    return [self[alias] for alias in self]
  File "/home/lsy/.virtualenvs/py3_django/lib/python3.5/site-packages/django/template/utils.py", line 89, in <listcomp>
    return [self[alias] for alias in self]
  File "/home/lsy/.virtualenvs/py3_django/lib/python3.5/site-packages/django/template/utils.py", line 80, in __getitem__
    engine = engine_cls(params)
  File "/home/lsy/.virtualenvs/py3_django/lib/python3.5/site-packages/django/template/backends/jinja2.py", line 29, in __init__
    environment_cls = import_string(environment)
  File "/home/lsy/.virtualenvs/py3_django/lib/python3.5/site-packages/django/utils/module_loading.py", line 20, in import_string
    module = import_module(module_path)
  File "/home/lsy/.virtualenvs/py3_django/lib/python3.5/importlib/__init__.py", line 126, in import_module
    return _bootstrap._gcd_import(name[level:], package, level)
  File "<frozen importlib._bootstrap>", line 986, in _gcd_import
  File "<frozen importlib._bootstrap>", line 969, in _find_and_load
  File "<frozen importlib._bootstrap>", line 956, in _find_and_load_unlocked
ImportError: No module named 'utils.jinja2_env'
ERROR 2019-06-12 09:01:51,945 basehttp 124 "GET /register/ HTTP/1.1" 500 126752
ERROR 2019-06-12 09:05:26,739 exception 135 Internal Server Error: /register/
Traceback (most recent call last):
  File "/home/lsy/.virtualenvs/py3_django/lib/python3.5/site-packages/django/template/utils.py", line 65, in __getitem__
    return self._engines[alias]
KeyError: 'jinja2'

During handling of the above exception, another exception occurred:

Traceback (most recent call last):
  File "/home/lsy/.virtualenvs/py3_django/lib/python3.5/site-packages/django/core/handlers/exception.py", line 41, in inner
    response = get_response(request)
  File "/home/lsy/.virtualenvs/py3_django/lib/python3.5/site-packages/django/core/handlers/base.py", line 187, in _get_response
    response = self.process_exception_by_middleware(e, request)
  File "/home/lsy/.virtualenvs/py3_django/lib/python3.5/site-packages/django/core/handlers/base.py", line 185, in _get_response
    response = wrapped_callback(request, *callback_args, **callback_kwargs)
  File "/home/lsy/.virtualenvs/py3_django/lib/python3.5/site-packages/django/views/generic/base.py", line 68, in view
    return self.dispatch(request, *args, **kwargs)
  File "/home/lsy/.virtualenvs/py3_django/lib/python3.5/site-packages/django/views/generic/base.py", line 88, in dispatch
    return handler(request, *args, **kwargs)
  File "/home/lsy/Desktop/project/meiduo/apps/users/views.py", line 10, in get
    return render(request, 'register.html')
  File "/home/lsy/.virtualenvs/py3_django/lib/python3.5/site-packages/django/shortcuts.py", line 30, in render
    content = loader.render_to_string(template_name, context, request, using=using)
  File "/home/lsy/.virtualenvs/py3_django/lib/python3.5/site-packages/django/template/loader.py", line 67, in render_to_string
    template = get_template(template_name, using=using)
  File "/home/lsy/.virtualenvs/py3_django/lib/python3.5/site-packages/django/template/loader.py", line 18, in get_template
    engines = _engine_list(using)
  File "/home/lsy/.virtualenvs/py3_django/lib/python3.5/site-packages/django/template/loader.py", line 72, in _engine_list
    return engines.all() if using is None else [engines[using]]
  File "/home/lsy/.virtualenvs/py3_django/lib/python3.5/site-packages/django/template/utils.py", line 89, in all
    return [self[alias] for alias in self]
  File "/home/lsy/.virtualenvs/py3_django/lib/python3.5/site-packages/django/template/utils.py", line 89, in <listcomp>
    return [self[alias] for alias in self]
  File "/home/lsy/.virtualenvs/py3_django/lib/python3.5/site-packages/django/template/utils.py", line 80, in __getitem__
    engine = engine_cls(params)
  File "/home/lsy/.virtualenvs/py3_django/lib/python3.5/site-packages/django/template/backends/jinja2.py", line 29, in __init__
    environment_cls = import_string(environment)
  File "/home/lsy/.virtualenvs/py3_django/lib/python3.5/site-packages/django/utils/module_loading.py", line 20, in import_string
    module = import_module(module_path)
  File "/home/lsy/.virtualenvs/py3_django/lib/python3.5/importlib/__init__.py", line 126, in import_module
    return _bootstrap._gcd_import(name[level:], package, level)
  File "<frozen importlib._bootstrap>", line 986, in _gcd_import
  File "<frozen importlib._bootstrap>", line 969, in _find_and_load
  File "<frozen importlib._bootstrap>", line 944, in _find_and_load_unlocked
  File "<frozen importlib._bootstrap>", line 222, in _call_with_frames_removed
  File "<frozen importlib._bootstrap>", line 986, in _gcd_import
  File "<frozen importlib._bootstrap>", line 969, in _find_and_load
  File "<frozen importlib._bootstrap>", line 956, in _find_and_load_unlocked
ImportError: No module named 'utils'
ERROR 2019-06-12 09:05:26,793 basehttp 124 "GET /register/ HTTP/1.1" 500 126708
INFO 2019-06-12 09:07:56,765 basehttp 124 "GET /register/ HTTP/1.1" 200 4891
INFO 2019-06-12 09:07:56,782 basehttp 124 "GET /static/js/axios-0.18.0.min.js HTTP/1.1" 200 12941
INFO 2019-06-12 09:07:56,783 basehttp 124 "GET /static/css/reset.css HTTP/1.1" 304 0
INFO 2019-06-12 09:07:56,787 basehttp 124 "GET /static/images/logo.png HTTP/1.1" 304 0
INFO 2019-06-12 09:07:56,788 basehttp 124 "GET /static/css/main.css HTTP/1.1" 304 0
INFO 2019-06-12 09:07:56,790 basehttp 124 "GET /static/images/pic_code.jpg HTTP/1.1" 304 0
INFO 2019-06-12 09:07:56,791 basehttp 124 "GET /static/js/vue-2.5.16.js HTTP/1.1" 200 289307
INFO 2019-06-12 09:07:56,796 basehttp 124 "GET /static/js/host.js HTTP/1.1" 304 0
INFO 2019-06-12 09:07:56,801 basehttp 124 "GET /static/js/common.js HTTP/1.1" 304 0
INFO 2019-06-12 09:07:56,807 basehttp 124 "GET /static/js/register.js HTTP/1.1" 304 0
INFO 2019-06-12 09:07:56,814 basehttp 124 "GET /static/images/interval_line.png HTTP/1.1" 304 0
INFO 2019-06-12 09:07:56,817 basehttp 124 "GET /static/images/register_banner.png HTTP/1.1" 304 0
INFO 2019-06-12 09:07:56,818 basehttp 124 "GET /static/images/icons02.png HTTP/1.1" 304 0
WARNING 2019-06-12 09:18:43,527 base 152 Not Found: /
WARNING 2019-06-12 09:18:43,529 basehttp 124 "GET / HTTP/1.1" 404 2070
INFO 2019-06-12 09:57:48,601 basehttp 124 "GET /register/ HTTP/1.1" 200 4891
INFO 2019-06-12 10:27:25,456 basehttp 124 "GET /register/ HTTP/1.1" 200 4891
INFO 2019-06-12 10:35:05,230 basehttp 124 "GET /register/ HTTP/1.1" 200 4891
INFO 2019-06-12 10:35:37,996 basehttp 124 "GET /register/ HTTP/1.1" 200 4891
INFO 2019-06-12 10:39:03,087 basehttp 124 "GET /register/ HTTP/1.1" 200 4891
INFO 2019-06-12 10:40:19,796 basehttp 124 "GET /register/ HTTP/1.1" 200 4891
INFO 2019-06-12 10:41:08,002 basehttp 124 "GET /register/ HTTP/1.1" 200 4891
INFO 2019-06-12 10:42:33,101 basehttp 124 "GET /register/ HTTP/1.1" 200 4891
INFO 2019-06-12 10:44:44,184 basehttp 124 "GET /register/ HTTP/1.1" 200 4891
INFO 2019-06-12 10:46:24,190 basehttp 124 "GET /register/ HTTP/1.1" 200 4889
INFO 2019-06-12 10:57:51,485 basehttp 124 "GET /register/ HTTP/1.1" 200 4890
INFO 2019-06-12 10:58:08,849 basehttp 124 "GET /register/ HTTP/1.1" 200 4890
INFO 2019-06-12 11:00:36,630 basehttp 124 "GET /register/ HTTP/1.1" 200 4864
INFO 2019-06-12 11:02:52,739 basehttp 124 "GET /register/ HTTP/1.1" 200 4864
INFO 2019-06-12 11:03:17,425 basehttp 124 "GET /register/ HTTP/1.1" 200 4864
INFO 2019-06-12 11:03:17,477 basehttp 124 "GET /static/css/reset.css HTTP/1.1" 200 638
INFO 2019-06-12 11:03:17,479 basehttp 124 "GET /static/css/main.css HTTP/1.1" 200 39722
INFO 2019-06-12 11:03:17,486 basehttp 124 "GET /static/js/axios-0.18.0.min.js HTTP/1.1" 200 12941
INFO 2019-06-12 11:03:17,489 basehttp 124 "GET /static/js/host.js HTTP/1.1" 200 80
INFO 2019-06-12 11:03:17,494 basehttp 124 "GET /static/js/register.js HTTP/1.1" 200 7743
INFO 2019-06-12 11:03:17,497 basehttp 124 "GET /static/js/vue-2.5.16.js HTTP/1.1" 200 289307
INFO 2019-06-12 11:03:17,498 basehttp 124 "GET /static/js/common.js HTTP/1.1" 200 891
INFO 2019-06-12 11:03:17,501 basehttp 124 "GET /static/images/logo.png HTTP/1.1" 200 7450
INFO 2019-06-12 11:03:17,504 basehttp 124 "GET /static/images/pic_code.jpg HTTP/1.1" 200 4507
INFO 2019-06-12 11:03:17,567 basehttp 124 "GET /static/images/interval_line.png HTTP/1.1" 200 1123
INFO 2019-06-12 11:03:17,572 basehttp 124 "GET /static/images/icons02.png HTTP/1.1" 200 3935
INFO 2019-06-12 11:03:17,573 basehttp 124 "GET /static/images/register_banner.png HTTP/1.1" 200 54894
WARNING 2019-06-12 11:03:17,595 base 152 Not Found: /favicon.ico
WARNING 2019-06-12 11:03:17,595 basehttp 124 "GET /favicon.ico HTTP/1.1" 404 2121
INFO 2019-06-12 11:04:17,380 basehttp 124 "GET /register/ HTTP/1.1" 200 4890
INFO 2019-06-12 11:04:17,396 basehttp 124 "GET /static/css/main.css HTTP/1.1" 304 0
INFO 2019-06-12 11:04:17,398 basehttp 124 "GET /static/css/reset.css HTTP/1.1" 304 0
INFO 2019-06-12 11:04:17,400 basehttp 124 "GET /static/js/vue-2.5.16.js HTTP/1.1" 304 0
INFO 2019-06-12 11:04:17,405 basehttp 124 "GET /static/js/common.js HTTP/1.1" 304 0
INFO 2019-06-12 11:04:17,405 basehttp 124 "GET /static/js/axios-0.18.0.min.js HTTP/1.1" 304 0
INFO 2019-06-12 11:04:17,410 basehttp 124 "GET /static/js/host.js HTTP/1.1" 304 0
INFO 2019-06-12 11:04:17,410 basehttp 124 "GET /static/js/register.js HTTP/1.1" 304 0
INFO 2019-06-12 11:04:17,429 basehttp 124 "GET /static/images/pic_code.jpg HTTP/1.1" 304 0
INFO 2019-06-12 11:04:17,429 basehttp 124 "GET /static/images/logo.png HTTP/1.1" 304 0
INFO 2019-06-12 11:04:17,473 basehttp 124 "GET /static/images/register_banner.png HTTP/1.1" 304 0
INFO 2019-06-12 11:04:17,474 basehttp 124 "GET /static/images/interval_line.png HTTP/1.1" 304 0
INFO 2019-06-12 11:04:17,475 basehttp 124 "GET /static/images/icons02.png HTTP/1.1" 304 0
INFO 2019-06-12 11:05:54,559 basehttp 124 "GET /register/ HTTP/1.1" 200 4890
INFO 2019-06-12 11:06:28,873 basehttp 124 "GET /register/ HTTP/1.1" 200 4890
INFO 2019-06-12 12:04:12,866 basehttp 124 "GET /register/ HTTP/1.1" 200 4890
INFO 2019-06-12 12:04:12,881 basehttp 124 "GET /static/css/reset.css HTTP/1.1" 304 0
INFO 2019-06-12 12:04:12,885 basehttp 124 "GET /static/css/main.css HTTP/1.1" 304 0
INFO 2019-06-12 12:04:12,889 basehttp 124 "GET /static/js/axios-0.18.0.min.js HTTP/1.1" 304 0
INFO 2019-06-12 12:04:12,891 basehttp 124 "GET /static/images/logo.png HTTP/1.1" 304 0
INFO 2019-06-12 12:04:12,891 basehttp 124 "GET /static/js/vue-2.5.16.js HTTP/1.1" 304 0
INFO 2019-06-12 12:04:12,891 basehttp 124 "GET /static/images/pic_code.jpg HTTP/1.1" 304 0
INFO 2019-06-12 12:04:12,912 basehttp 124 "GET /static/js/host.js HTTP/1.1" 304 0
INFO 2019-06-12 12:04:12,913 basehttp 124 "GET /static/js/common.js HTTP/1.1" 304 0
INFO 2019-06-12 12:04:12,916 basehttp 124 "GET /static/images/interval_line.png HTTP/1.1" 304 0
INFO 2019-06-12 12:04:12,918 basehttp 124 "GET /static/images/icons02.png HTTP/1.1" 304 0
INFO 2019-06-12 12:04:12,918 basehttp 124 "GET /static/images/register_banner.png HTTP/1.1" 304 0
INFO 2019-06-12 12:04:12,919 basehttp 124 "GET /static/js/register.js HTTP/1.1" 200 7743
ERROR 2019-06-12 12:04:52,395 exception 135 Internal Server Error: /register/
Traceback (most recent call last):
  File "/home/lsy/.virtualenvs/py3_django/lib/python3.5/site-packages/django/core/handlers/exception.py", line 41, in inner
    response = get_response(request)
  File "/home/lsy/.virtualenvs/py3_django/lib/python3.5/site-packages/django/core/handlers/base.py", line 187, in _get_response
    response = self.process_exception_by_middleware(e, request)
  File "/home/lsy/.virtualenvs/py3_django/lib/python3.5/site-packages/django/core/handlers/base.py", line 185, in _get_response
    response = wrapped_callback(request, *callback_args, **callback_kwargs)
  File "/home/lsy/.virtualenvs/py3_django/lib/python3.5/site-packages/django/views/generic/base.py", line 68, in view
    return self.dispatch(request, *args, **kwargs)
  File "/home/lsy/.virtualenvs/py3_django/lib/python3.5/site-packages/django/views/generic/base.py", line 88, in dispatch
    return handler(request, *args, **kwargs)
  File "/home/lsy/Desktop/project/meiduo/apps/users/views.py", line 27, in post
    if not re.match(r'[a-zA-Z0-9_]{8,20}'):
TypeError: match() missing 1 required positional argument: 'string'
ERROR 2019-06-12 12:04:52,434 basehttp 124 "POST /register/ HTTP/1.1" 500 84095
ERROR 2019-06-12 12:07:26,490 exception 135 Internal Server Error: /register/
Traceback (most recent call last):
  File "/home/lsy/.virtualenvs/py3_django/lib/python3.5/site-packages/django/core/handlers/exception.py", line 41, in inner
    response = get_response(request)
  File "/home/lsy/.virtualenvs/py3_django/lib/python3.5/site-packages/django/core/handlers/base.py", line 187, in _get_response
    response = self.process_exception_by_middleware(e, request)
  File "/home/lsy/.virtualenvs/py3_django/lib/python3.5/site-packages/django/core/handlers/base.py", line 185, in _get_response
    response = wrapped_callback(request, *callback_args, **callback_kwargs)
  File "/home/lsy/.virtualenvs/py3_django/lib/python3.5/site-packages/django/views/generic/base.py", line 68, in view
    return self.dispatch(request, *args, **kwargs)
  File "/home/lsy/.virtualenvs/py3_django/lib/python3.5/site-packages/django/views/generic/base.py", line 88, in dispatch
    return handler(request, *args, **kwargs)
  File "/home/lsy/Desktop/project/meiduo/apps/users/views.py", line 38, in post
    return redirect(reversed('register:contents'))
  File "/home/lsy/.virtualenvs/py3_django/lib/python3.5/site-packages/django/shortcuts.py", line 56, in redirect
    return redirect_class(resolve_url(to, *args, **kwargs))
  File "/home/lsy/.virtualenvs/py3_django/lib/python3.5/site-packages/django/shortcuts.py", line 147, in resolve_url
    return reverse(to, args=args, kwargs=kwargs)
  File "/home/lsy/.virtualenvs/py3_django/lib/python3.5/site-packages/django/urls/base.py", line 91, in reverse
    return force_text(iri_to_uri(resolver._reverse_with_prefix(view, prefix, *args, **kwargs)))
  File "/home/lsy/.virtualenvs/py3_django/lib/python3.5/site-packages/django/urls/resolvers.py", line 497, in _reverse_with_prefix
    raise NoReverseMatch(msg)
django.urls.exceptions.NoReverseMatch: Reverse for '<reversed object at 0x7f6e9c3b2a20>' not found. '<reversed object at 0x7f6e9c3b2a20>' is not a valid view function or pattern name.
ERROR 2019-06-12 12:07:26,531 basehttp 124 "POST /register/ HTTP/1.1" 500 103698
INFO 2019-06-12 12:09:19,234 basehttp 124 "POST /register/ HTTP/1.1" 200 4996
INFO 2019-06-12 12:09:19,257 basehttp 124 "GET /static/css/main.css HTTP/1.1" 304 0
INFO 2019-06-12 12:09:19,258 basehttp 124 "GET /static/css/reset.css HTTP/1.1" 304 0
INFO 2019-06-12 12:09:19,266 basehttp 124 "GET /static/js/vue-2.5.16.js HTTP/1.1" 304 0
INFO 2019-06-12 12:09:19,268 basehttp 124 "GET /static/js/host.js HTTP/1.1" 304 0
INFO 2019-06-12 12:09:19,273 basehttp 124 "GET /static/js/axios-0.18.0.min.js HTTP/1.1" 304 0
INFO 2019-06-12 12:09:19,273 basehttp 124 "GET /static/js/register.js HTTP/1.1" 304 0
INFO 2019-06-12 12:09:19,273 basehttp 124 "GET /static/js/common.js HTTP/1.1" 304 0
INFO 2019-06-12 12:09:19,293 basehttp 124 "GET /static/images/logo.png HTTP/1.1" 304 0
INFO 2019-06-12 12:09:19,293 basehttp 124 "GET /static/images/pic_code.jpg HTTP/1.1" 304 0
INFO 2019-06-12 12:09:19,343 basehttp 124 "GET /static/images/register_banner.png HTTP/1.1" 304 0
INFO 2019-06-12 12:09:19,347 basehttp 124 "GET /static/images/interval_line.png HTTP/1.1" 304 0
INFO 2019-06-12 12:09:19,348 basehttp 124 "GET /static/images/icons02.png HTTP/1.1" 304 0
INFO 2019-06-12 12:10:42,557 basehttp 124 "POST /register/ HTTP/1.1" 200 4996
ERROR 2019-06-12 12:15:04,195 exception 135 Internal Server Error: /register/
Traceback (most recent call last):
  File "/home/lsy/.virtualenvs/py3_django/lib/python3.5/site-packages/django/core/handlers/exception.py", line 41, in inner
    response = get_response(request)
  File "/home/lsy/.virtualenvs/py3_django/lib/python3.5/site-packages/django/core/handlers/base.py", line 187, in _get_response
    response = self.process_exception_by_middleware(e, request)
  File "/home/lsy/.virtualenvs/py3_django/lib/python3.5/site-packages/django/core/handlers/base.py", line 185, in _get_response
    response = wrapped_callback(request, *callback_args, **callback_kwargs)
  File "/home/lsy/.virtualenvs/py3_django/lib/python3.5/site-packages/django/views/generic/base.py", line 68, in view
    return self.dispatch(request, *args, **kwargs)
  File "/home/lsy/.virtualenvs/py3_django/lib/python3.5/site-packages/django/views/generic/base.py", line 88, in dispatch
    return handler(request, *args, **kwargs)
  File "/home/lsy/Desktop/project/meiduo/apps/users/views.py", line 38, in post
    return redirect(reversed('register:contents'))
  File "/home/lsy/.virtualenvs/py3_django/lib/python3.5/site-packages/django/shortcuts.py", line 56, in redirect
    return redirect_class(resolve_url(to, *args, **kwargs))
  File "/home/lsy/.virtualenvs/py3_django/lib/python3.5/site-packages/django/shortcuts.py", line 147, in resolve_url
    return reverse(to, args=args, kwargs=kwargs)
  File "/home/lsy/.virtualenvs/py3_django/lib/python3.5/site-packages/django/urls/base.py", line 91, in reverse
    return force_text(iri_to_uri(resolver._reverse_with_prefix(view, prefix, *args, **kwargs)))
  File "/home/lsy/.virtualenvs/py3_django/lib/python3.5/site-packages/django/urls/resolvers.py", line 497, in _reverse_with_prefix
    raise NoReverseMatch(msg)
django.urls.exceptions.NoReverseMatch: Reverse for '<reversed object at 0x7fc1caa194a8>' not found. '<reversed object at 0x7fc1caa194a8>' is not a valid view function or pattern name.
ERROR 2019-06-12 12:15:47,548 basehttp 124 "POST /register/ HTTP/1.1" 500 105479
INFO 2019-06-12 12:20:08,635 basehttp 124 "POST /register/ HTTP/1.1" 200 4996
INFO 2019-06-12 12:20:08,663 basehttp 124 "GET /static/js/host.js HTTP/1.1" 304 0
INFO 2019-06-12 12:20:08,664 basehttp 124 "GET /static/css/reset.css HTTP/1.1" 304 0
INFO 2019-06-12 12:20:08,665 basehttp 124 "GET /static/js/vue-2.5.16.js HTTP/1.1" 304 0
INFO 2019-06-12 12:20:08,668 basehttp 124 "GET /static/css/main.css HTTP/1.1" 304 0
INFO 2019-06-12 12:20:08,670 basehttp 124 "GET /static/js/axios-0.18.0.min.js HTTP/1.1" 304 0
INFO 2019-06-12 12:20:08,678 basehttp 124 "GET /static/js/common.js HTTP/1.1" 304 0
INFO 2019-06-12 12:20:08,681 basehttp 124 "GET /static/js/register.js HTTP/1.1" 304 0
INFO 2019-06-12 12:20:08,703 basehttp 124 "GET /static/images/pic_code.jpg HTTP/1.1" 304 0
INFO 2019-06-12 12:20:08,704 basehttp 124 "GET /static/images/logo.png HTTP/1.1" 304 0
INFO 2019-06-12 12:20:08,741 basehttp 124 "GET /static/images/register_banner.png HTTP/1.1" 304 0
INFO 2019-06-12 12:20:08,743 basehttp 124 "GET /static/images/interval_line.png HTTP/1.1" 304 0
INFO 2019-06-12 12:20:08,745 basehttp 124 "GET /static/images/icons02.png HTTP/1.1" 304 0
WARNING 2019-06-12 12:24:53,600 basehttp 124 "POST /register/ HTTP/1.1" 400 12
INFO 2019-06-12 12:26:26,457 basehttp 124 "POST /register/ HTTP/1.1" 200 6
ERROR 2019-06-12 12:42:36,951 exception 135 Internal Server Error: /register/
Traceback (most recent call last):
  File "/home/lsy/.virtualenvs/py3_django/lib/python3.5/site-packages/django_redis/cache.py", line 32, in _decorator
    return method(self, *args, **kwargs)
  File "/home/lsy/.virtualenvs/py3_django/lib/python3.5/site-packages/django_redis/cache.py", line 124, in has_key
    return self.client.has_key(*args, **kwargs)
  File "/home/lsy/.virtualenvs/py3_django/lib/python3.5/site-packages/django_redis/client/default.py", line 478, in has_key
    raise ConnectionInterrupted(connection=client, parent=e)
django_redis.exceptions.ConnectionInterrupted: Redis ConnectionError: Error 111 connecting to 127.0.0.1:6379. Connection refused.

During handling of the above exception, another exception occurred:

Traceback (most recent call last):
  File "/home/lsy/.virtualenvs/py3_django/lib/python3.5/site-packages/django/core/handlers/exception.py", line 41, in inner
    response = get_response(request)
  File "/home/lsy/.virtualenvs/py3_django/lib/python3.5/site-packages/django/core/handlers/base.py", line 187, in _get_response
    response = self.process_exception_by_middleware(e, request)
  File "/home/lsy/.virtualenvs/py3_django/lib/python3.5/site-packages/django/core/handlers/base.py", line 185, in _get_response
    response = wrapped_callback(request, *callback_args, **callback_kwargs)
  File "/home/lsy/.virtualenvs/py3_django/lib/python3.5/site-packages/django/views/generic/base.py", line 68, in view
    return self.dispatch(request, *args, **kwargs)
  File "/home/lsy/.virtualenvs/py3_django/lib/python3.5/site-packages/django/views/generic/base.py", line 88, in dispatch
    return handler(request, *args, **kwargs)
  File "/home/lsy/Desktop/project/meiduo/apps/users/views.py", line 40, in post
    login(request, username)
  File "/home/lsy/.virtualenvs/py3_django/lib/python3.5/site-packages/django/contrib/auth/__init__.py", line 140, in login
    request.session.cycle_key()
  File "/home/lsy/.virtualenvs/py3_django/lib/python3.5/site-packages/django/contrib/sessions/backends/base.py", line 311, in cycle_key
    self.create()
  File "/home/lsy/.virtualenvs/py3_django/lib/python3.5/site-packages/django/contrib/sessions/backends/cache.py", line 44, in create
    self._session_key = self._get_new_session_key()
  File "/home/lsy/.virtualenvs/py3_django/lib/python3.5/site-packages/django/contrib/sessions/backends/base.py", line 164, in _get_new_session_key
    if not self.exists(session_key):
  File "/home/lsy/.virtualenvs/py3_django/lib/python3.5/site-packages/django/contrib/sessions/backends/cache.py", line 71, in exists
    return session_key and (self.cache_key_prefix + session_key) in self._cache
  File "/home/lsy/.virtualenvs/py3_django/lib/python3.5/site-packages/django/core/cache/backends/base.py", line 203, in __contains__
    return self.has_key(key)
  File "/home/lsy/.virtualenvs/py3_django/lib/python3.5/site-packages/django_redis/cache.py", line 39, in _decorator
    raise e.parent
  File "/home/lsy/.virtualenvs/py3_django/lib/python3.5/site-packages/django_redis/client/default.py", line 476, in has_key
    return client.exists(key) == 1
  File "/home/lsy/.virtualenvs/py3_django/lib/python3.5/site-packages/redis/client.py", line 1239, in exists
    return self.execute_command('EXISTS', *names)
  File "/home/lsy/.virtualenvs/py3_django/lib/python3.5/site-packages/redis/client.py", line 772, in execute_command
    connection = pool.get_connection(command_name, **options)
  File "/home/lsy/.virtualenvs/py3_django/lib/python3.5/site-packages/redis/connection.py", line 994, in get_connection
    connection.connect()
  File "/home/lsy/.virtualenvs/py3_django/lib/python3.5/site-packages/redis/connection.py", line 497, in connect
    raise ConnectionError(self._error_message(e))
redis.exceptions.ConnectionError: Error 111 connecting to 127.0.0.1:6379. Connection refused.
ERROR 2019-06-12 12:42:37,016 basehttp 124 "POST /register/ HTTP/1.1" 500 146890
INFO 2019-06-12 12:43:40,783 basehttp 124 "POST /register/ HTTP/1.1" 200 4996
INFO 2019-06-12 12:43:40,810 basehttp 124 "GET /static/css/reset.css HTTP/1.1" 304 0
INFO 2019-06-12 12:43:40,815 basehttp 124 "GET /static/js/vue-2.5.16.js HTTP/1.1" 304 0
INFO 2019-06-12 12:43:40,818 basehttp 124 "GET /static/js/axios-0.18.0.min.js HTTP/1.1" 304 0
INFO 2019-06-12 12:43:40,819 basehttp 124 "GET /static/js/host.js HTTP/1.1" 304 0
INFO 2019-06-12 12:43:40,824 basehttp 124 "GET /static/css/main.css HTTP/1.1" 304 0
INFO 2019-06-12 12:43:40,828 basehttp 124 "GET /static/js/common.js HTTP/1.1" 304 0
INFO 2019-06-12 12:43:40,825 basehttp 124 "GET /static/js/register.js HTTP/1.1" 304 0
INFO 2019-06-12 12:43:40,839 basehttp 124 "GET /static/images/logo.png HTTP/1.1" 304 0
INFO 2019-06-12 12:43:40,844 basehttp 124 "GET /static/images/pic_code.jpg HTTP/1.1" 304 0
INFO 2019-06-12 12:43:40,849 basehttp 124 "GET /static/images/icons02.png HTTP/1.1" 304 0
INFO 2019-06-12 12:43:40,850 basehttp 124 "GET /static/images/register_banner.png HTTP/1.1" 304 0
INFO 2019-06-12 12:43:40,851 basehttp 124 "GET /static/images/interval_line.png HTTP/1.1" 304 0
INFO 2019-06-12 12:43:40,885 basehttp 124 "GET /static/images/logo.png HTTP/1.1" 304 0
ERROR 2019-06-12 12:44:24,042 exception 135 Internal Server Error: /register/
Traceback (most recent call last):
  File "/home/lsy/.virtualenvs/py3_django/lib/python3.5/site-packages/django_redis/cache.py", line 32, in _decorator
    return method(self, *args, **kwargs)
  File "/home/lsy/.virtualenvs/py3_django/lib/python3.5/site-packages/django_redis/cache.py", line 124, in has_key
    return self.client.has_key(*args, **kwargs)
  File "/home/lsy/.virtualenvs/py3_django/lib/python3.5/site-packages/django_redis/client/default.py", line 478, in has_key
    raise ConnectionInterrupted(connection=client, parent=e)
django_redis.exceptions.ConnectionInterrupted: Redis ConnectionError: Error 111 connecting to 127.0.0.1:6379. Connection refused.

During handling of the above exception, another exception occurred:

Traceback (most recent call last):
  File "/home/lsy/.virtualenvs/py3_django/lib/python3.5/site-packages/django/core/handlers/exception.py", line 41, in inner
    response = get_response(request)
  File "/home/lsy/.virtualenvs/py3_django/lib/python3.5/site-packages/django/core/handlers/base.py", line 187, in _get_response
    response = self.process_exception_by_middleware(e, request)
  File "/home/lsy/.virtualenvs/py3_django/lib/python3.5/site-packages/django/core/handlers/base.py", line 185, in _get_response
    response = wrapped_callback(request, *callback_args, **callback_kwargs)
  File "/home/lsy/.virtualenvs/py3_django/lib/python3.5/site-packages/django/views/generic/base.py", line 68, in view
    return self.dispatch(request, *args, **kwargs)
  File "/home/lsy/.virtualenvs/py3_django/lib/python3.5/site-packages/django/views/generic/base.py", line 88, in dispatch
    return handler(request, *args, **kwargs)
  File "/home/lsy/Desktop/project/meiduo/apps/users/views.py", line 40, in post
    login(request,user)
  File "/home/lsy/.virtualenvs/py3_django/lib/python3.5/site-packages/django/contrib/auth/__init__.py", line 140, in login
    request.session.cycle_key()
  File "/home/lsy/.virtualenvs/py3_django/lib/python3.5/site-packages/django/contrib/sessions/backends/base.py", line 311, in cycle_key
    self.create()
  File "/home/lsy/.virtualenvs/py3_django/lib/python3.5/site-packages/django/contrib/sessions/backends/cache.py", line 44, in create
    self._session_key = self._get_new_session_key()
  File "/home/lsy/.virtualenvs/py3_django/lib/python3.5/site-packages/django/contrib/sessions/backends/base.py", line 164, in _get_new_session_key
    if not self.exists(session_key):
  File "/home/lsy/.virtualenvs/py3_django/lib/python3.5/site-packages/django/contrib/sessions/backends/cache.py", line 71, in exists
    return session_key and (self.cache_key_prefix + session_key) in self._cache
  File "/home/lsy/.virtualenvs/py3_django/lib/python3.5/site-packages/django/core/cache/backends/base.py", line 203, in __contains__
    return self.has_key(key)
  File "/home/lsy/.virtualenvs/py3_django/lib/python3.5/site-packages/django_redis/cache.py", line 39, in _decorator
    raise e.parent
  File "/home/lsy/.virtualenvs/py3_django/lib/python3.5/site-packages/django_redis/client/default.py", line 476, in has_key
    return client.exists(key) == 1
  File "/home/lsy/.virtualenvs/py3_django/lib/python3.5/site-packages/redis/client.py", line 1239, in exists
    return self.execute_command('EXISTS', *names)
  File "/home/lsy/.virtualenvs/py3_django/lib/python3.5/site-packages/redis/client.py", line 772, in execute_command
    connection = pool.get_connection(command_name, **options)
  File "/home/lsy/.virtualenvs/py3_django/lib/python3.5/site-packages/redis/connection.py", line 994, in get_connection
    connection.connect()
  File "/home/lsy/.virtualenvs/py3_django/lib/python3.5/site-packages/redis/connection.py", line 497, in connect
    raise ConnectionError(self._error_message(e))
redis.exceptions.ConnectionError: Error 111 connecting to 127.0.0.1:6379. Connection refused.
ERROR 2019-06-12 12:44:24,098 basehttp 124 "POST /register/ HTTP/1.1" 500 147478
WARNING 2019-06-12 12:44:37,521 base 152 Not Found: /
WARNING 2019-06-12 12:44:37,521 basehttp 124 "GET / HTTP/1.1" 404 2263
INFO 2019-06-12 12:45:06,377 basehttp 124 "GET /static/images/interval_line.png HTTP/1.1" 304 0
INFO 2019-06-12 12:45:06,385 basehttp 124 "GET /static/images/register_banner.png HTTP/1.1" 304 0
INFO 2019-06-12 12:45:06,387 basehttp 124 "GET /static/images/icons02.png HTTP/1.1" 304 0
INFO 2019-06-13 06:04:44,699 basehttp 124 "GET /register/ HTTP/1.1" 200 4890
INFO 2019-06-13 06:04:44,762 basehttp 124 "GET /static/css/main.css HTTP/1.1" 304 0
INFO 2019-06-13 06:04:44,774 basehttp 124 "GET /static/js/axios-0.18.0.min.js HTTP/1.1" 304 0
INFO 2019-06-13 06:04:44,779 basehttp 124 "GET /static/js/host.js HTTP/1.1" 304 0
INFO 2019-06-13 06:04:44,780 basehttp 124 "GET /static/js/vue-2.5.16.js HTTP/1.1" 304 0
INFO 2019-06-13 06:04:44,780 basehttp 124 "GET /static/css/reset.css HTTP/1.1" 304 0
INFO 2019-06-13 06:04:44,788 basehttp 124 "GET /static/js/common.js HTTP/1.1" 304 0
INFO 2019-06-13 06:04:44,793 basehttp 124 "GET /static/images/logo.png HTTP/1.1" 304 0
INFO 2019-06-13 06:04:44,795 basehttp 124 "GET /static/js/register.js HTTP/1.1" 200 9433
INFO 2019-06-13 06:04:44,796 basehttp 124 "GET /static/images/pic_code.jpg HTTP/1.1" 304 0
INFO 2019-06-13 06:04:44,808 basehttp 124 "GET /static/images/interval_line.png HTTP/1.1" 304 0
INFO 2019-06-13 06:04:44,812 basehttp 124 "GET /static/images/register_banner.png HTTP/1.1" 304 0
INFO 2019-06-13 06:04:44,813 basehttp 124 "GET /static/images/icons02.png HTTP/1.1" 304 0
INFO 2019-06-13 06:05:22,103 basehttp 124 "GET /register/ HTTP/1.1" 200 4890
INFO 2019-06-13 06:05:22,129 basehttp 124 "GET /static/css/main.css HTTP/1.1" 304 0
INFO 2019-06-13 06:05:22,131 basehttp 124 "GET /static/css/reset.css HTTP/1.1" 304 0
INFO 2019-06-13 06:05:22,136 basehttp 124 "GET /static/js/axios-0.18.0.min.js HTTP/1.1" 304 0
INFO 2019-06-13 06:05:22,137 basehttp 124 "GET /static/images/pic_code.jpg HTTP/1.1" 304 0
INFO 2019-06-13 06:05:22,137 basehttp 124 "GET /static/js/vue-2.5.16.js HTTP/1.1" 304 0
INFO 2019-06-13 06:05:22,142 basehttp 124 "GET /static/js/host.js HTTP/1.1" 304 0
INFO 2019-06-13 06:05:22,146 basehttp 124 "GET /static/js/common.js HTTP/1.1" 304 0
INFO 2019-06-13 06:05:22,150 basehttp 124 "GET /static/js/register.js HTTP/1.1" 200 8463
INFO 2019-06-13 06:05:22,159 basehttp 124 "GET /static/images/logo.png HTTP/1.1" 304 0
INFO 2019-06-13 06:05:22,177 basehttp 124 "GET /static/images/interval_line.png HTTP/1.1" 304 0
INFO 2019-06-13 06:05:22,178 basehttp 124 "GET /static/images/register_banner.png HTTP/1.1" 304 0
INFO 2019-06-13 06:05:22,180 basehttp 124 "GET /static/images/icons02.png HTTP/1.1" 304 0
INFO 2019-06-13 06:05:23,095 basehttp 124 "GET /register/ HTTP/1.1" 200 4890
INFO 2019-06-13 06:05:23,110 basehttp 124 "GET /static/js/register.js HTTP/1.1" 304 0
WARNING 2019-06-13 06:05:26,636 base 152 Not Found: /usernames/bnjiiii/count/
WARNING 2019-06-13 06:05:26,639 basehttp 124 "GET /usernames/bnjiiii/count/ HTTP/1.1" 404 2353
WARNING 2019-06-13 06:05:35,974 base 152 Not Found: /usernames/bnjiiii/count/
WARNING 2019-06-13 06:05:35,974 basehttp 124 "GET /usernames/bnjiiii/count/ HTTP/1.1" 404 2353
ERROR 2019-06-13 06:05:35,999 exception 135 Internal Server Error: /register/
Traceback (most recent call last):
  File "/home/lsy/.virtualenvs/py3_django/lib/python3.5/site-packages/django/core/handlers/exception.py", line 41, in inner
    response = get_response(request)
  File "/home/lsy/.virtualenvs/py3_django/lib/python3.5/site-packages/django/core/handlers/base.py", line 187, in _get_response
    response = self.process_exception_by_middleware(e, request)
  File "/home/lsy/.virtualenvs/py3_django/lib/python3.5/site-packages/django/core/handlers/base.py", line 185, in _get_response
    response = wrapped_callback(request, *callback_args, **callback_kwargs)
  File "/home/lsy/.virtualenvs/py3_django/lib/python3.5/site-packages/django/views/generic/base.py", line 68, in view
    return self.dispatch(request, *args, **kwargs)
  File "/home/lsy/.virtualenvs/py3_django/lib/python3.5/site-packages/django/views/generic/base.py", line 88, in dispatch
    return handler(request, *args, **kwargs)
  File "/home/lsy/Desktop/project/meiduo/apps/users/views.py", line 41, in post
    return http.JsonResponse()
TypeError: __init__() missing 1 required positional argument: 'data'
ERROR 2019-06-13 06:05:36,035 basehttp 124 "POST /register/ HTTP/1.1" 500 84554
WARNING 2019-06-13 06:09:00,594 basehttp 124 "POST /register/ HTTP/1.1" 400 18
INFO 2019-06-13 06:11:15,456 basehttp 124 "GET /register/ HTTP/1.1" 200 4890
INFO 2019-06-13 06:11:15,477 basehttp 124 "GET /static/css/reset.css HTTP/1.1" 304 0
INFO 2019-06-13 06:11:15,478 basehttp 124 "GET /static/css/main.css HTTP/1.1" 304 0
INFO 2019-06-13 06:11:15,483 basehttp 124 "GET /static/js/axios-0.18.0.min.js HTTP/1.1" 304 0
INFO 2019-06-13 06:11:15,485 basehttp 124 "GET /static/js/host.js HTTP/1.1" 304 0
INFO 2019-06-13 06:11:15,488 basehttp 124 "GET /static/js/vue-2.5.16.js HTTP/1.1" 304 0
INFO 2019-06-13 06:11:15,489 basehttp 124 "GET /static/js/common.js HTTP/1.1" 304 0
INFO 2019-06-13 06:11:15,490 basehttp 124 "GET /static/js/register.js HTTP/1.1" 200 8463
INFO 2019-06-13 06:11:15,513 basehttp 124 "GET /static/images/pic_code.jpg HTTP/1.1" 304 0
INFO 2019-06-13 06:11:15,514 basehttp 124 "GET /static/images/logo.png HTTP/1.1" 304 0
INFO 2019-06-13 06:11:15,555 basehttp 124 "GET /static/images/register_banner.png HTTP/1.1" 304 0
INFO 2019-06-13 06:11:15,555 basehttp 124 "GET /static/images/interval_line.png HTTP/1.1" 304 0
INFO 2019-06-13 06:11:15,557 basehttp 124 "GET /static/images/icons02.png HTTP/1.1" 304 0
WARNING 2019-06-13 06:11:23,619 base 152 Not Found: /usernames/liushiyu/count/
WARNING 2019-06-13 06:11:23,620 basehttp 124 "GET /usernames/liushiyu/count/ HTTP/1.1" 404 2356
INFO 2019-06-13 06:11:36,285 basehttp 124 "POST /register/ HTTP/1.1" 200 12
INFO 2019-06-13 06:11:41,916 basehttp 124 "GET /register/ HTTP/1.1" 200 4890
WARNING 2019-06-13 06:20:18,762 base 152 Not Found: /usernames//count/
WARNING 2019-06-13 06:20:18,763 basehttp 124 "GET /usernames//count/ HTTP/1.1" 404 2536
WARNING 2019-06-13 06:20:24,175 base 152 Not Found: /usernames/123123/count/
WARNING 2019-06-13 06:20:24,175 basehttp 124 "GET /usernames/123123/count/ HTTP/1.1" 404 2554
INFO 2019-06-13 06:20:32,877 basehttp 124 "POST /register/ HTTP/1.1" 200 4996
INFO 2019-06-13 06:20:32,938 basehttp 124 "GET /static/js/register.js HTTP/1.1" 304 0
INFO 2019-06-13 06:21:08,375 basehttp 124 "GET /register/ HTTP/1.1" 200 4890
WARNING 2019-06-13 06:21:13,953 base 152 Not Found: /usernames/123123/count/
WARNING 2019-06-13 06:21:13,953 basehttp 124 "GET /usernames/123123/count/ HTTP/1.1" 404 2554
WARNING 2019-06-13 06:21:40,041 base 152 Not Found: /usernames/liushiyu/count/
WARNING 2019-06-13 06:21:40,041 basehttp 124 "GET /usernames/liushiyu/count/ HTTP/1.1" 404 2560
WARNING 2019-06-13 06:22:36,542 base 152 Not Found: /usernames/liushiyu/count/
WARNING 2019-06-13 06:22:36,542 basehttp 124 "GET /usernames/liushiyu/count/ HTTP/1.1" 404 2582
WARNING 2019-06-13 06:23:02,006 base 152 Not Found: /usernames/liushiyu /count/
WARNING 2019-06-13 06:23:02,007 basehttp 124 "GET /usernames/liushiyu%20/count/ HTTP/1.1" 404 2587
WARNING 2019-06-13 06:24:20,417 base 152 Not Found: /usernames/123123/count/
WARNING 2019-06-13 06:24:20,418 basehttp 124 "GET /usernames/123123/count/ HTTP/1.1" 404 2576
INFO 2019-06-13 06:24:57,422 basehttp 124 "GET /usernames/1231231/count/ HTTP/1.1" 200 23
INFO 2019-06-13 06:25:57,639 basehttp 124 "GET /register/ HTTP/1.1" 200 4890
INFO 2019-06-13 06:25:57,723 basehttp 124 "GET /static/js/axios-0.18.0.min.js HTTP/1.1" 304 0
INFO 2019-06-13 06:25:57,724 basehttp 124 "GET /static/js/host.js HTTP/1.1" 304 0
INFO 2019-06-13 06:25:57,726 basehttp 124 "GET /static/css/main.css HTTP/1.1" 304 0
INFO 2019-06-13 06:25:57,730 basehttp 124 "GET /static/js/vue-2.5.16.js HTTP/1.1" 304 0
INFO 2019-06-13 06:25:57,736 basehttp 124 "GET /static/js/register.js HTTP/1.1" 304 0
INFO 2019-06-13 06:25:57,737 basehttp 124 "GET /static/css/reset.css HTTP/1.1" 304 0
INFO 2019-06-13 06:25:57,740 basehttp 124 "GET /static/js/common.js HTTP/1.1" 304 0
INFO 2019-06-13 06:25:57,904 basehttp 124 "GET /static/images/logo.png HTTP/1.1" 304 0
INFO 2019-06-13 06:25:57,904 basehttp 124 "GET /static/images/pic_code.jpg HTTP/1.1" 304 0
INFO 2019-06-13 06:25:57,956 basehttp 124 "GET /static/images/interval_line.png HTTP/1.1" 304 0
INFO 2019-06-13 06:25:57,968 basehttp 124 "GET /static/images/register_banner.png HTTP/1.1" 304 0
INFO 2019-06-13 06:25:57,968 basehttp 124 "GET /static/images/icons02.png HTTP/1.1" 304 0
INFO 2019-06-13 06:26:00,522 basehttp 124 "GET /usernames/1231231/count/ HTTP/1.1" 200 23
INFO 2019-06-13 06:26:00,531 basehttp 124 "GET /usernames/1231231/count/ HTTP/1.1" 200 23
INFO 2019-06-13 06:26:11,007 basehttp 124 "GET /usernames/1231231/count/ HTTP/1.1" 200 23
INFO 2019-06-13 06:31:03,452 basehttp 124 "GET /register/ HTTP/1.1" 200 4890
INFO 2019-06-13 06:31:03,497 basehttp 124 "GET /static/css/reset.css HTTP/1.1" 304 0
INFO 2019-06-13 06:31:03,500 basehttp 124 "GET /static/js/axios-0.18.0.min.js HTTP/1.1" 304 0
INFO 2019-06-13 06:31:03,504 basehttp 124 "GET /static/css/main.css HTTP/1.1" 304 0
INFO 2019-06-13 06:31:03,504 basehttp 124 "GET /static/js/host.js HTTP/1.1" 304 0
INFO 2019-06-13 06:31:03,505 basehttp 124 "GET /static/js/vue-2.5.16.js HTTP/1.1" 304 0
INFO 2019-06-13 06:31:03,511 basehttp 124 "GET /static/js/common.js HTTP/1.1" 304 0
INFO 2019-06-13 06:31:03,511 basehttp 124 "GET /static/js/register.js HTTP/1.1" 200 9068
INFO 2019-06-13 06:31:03,582 basehttp 124 "GET /static/images/logo.png HTTP/1.1" 304 0
INFO 2019-06-13 06:31:03,582 basehttp 124 "GET /static/images/pic_code.jpg HTTP/1.1" 304 0
INFO 2019-06-13 06:31:03,605 basehttp 124 "GET /static/images/interval_line.png HTTP/1.1" 304 0
INFO 2019-06-13 06:31:03,609 basehttp 124 "GET /static/images/register_banner.png HTTP/1.1" 304 0
INFO 2019-06-13 06:31:03,611 basehttp 124 "GET /static/images/icons02.png HTTP/1.1" 304 0
INFO 2019-06-13 06:31:12,096 basehttp 124 "GET /mobile/13456789986/count/ HTTP/1.1" 200 23
INFO 2019-06-13 06:31:54,042 basehttp 124 "GET /register/ HTTP/1.1" 200 4890
INFO 2019-06-13 06:31:54,076 basehttp 124 "GET /static/css/reset.css HTTP/1.1" 304 0
INFO 2019-06-13 06:31:54,079 basehttp 124 "GET /static/js/vue-2.5.16.js HTTP/1.1" 304 0
INFO 2019-06-13 06:31:54,081 basehttp 124 "GET /static/css/main.css HTTP/1.1" 304 0
INFO 2019-06-13 06:31:54,083 basehttp 124 "GET /static/js/axios-0.18.0.min.js HTTP/1.1" 304 0
INFO 2019-06-13 06:31:54,089 basehttp 124 "GET /static/js/common.js HTTP/1.1" 304 0
INFO 2019-06-13 06:31:54,091 basehttp 124 "GET /static/js/host.js HTTP/1.1" 304 0
INFO 2019-06-13 06:31:54,091 basehttp 124 "GET /static/js/register.js HTTP/1.1" 200 9068
INFO 2019-06-13 06:31:54,190 basehttp 124 "GET /static/images/pic_code.jpg HTTP/1.1" 304 0
INFO 2019-06-13 06:31:54,191 basehttp 124 "GET /static/images/logo.png HTTP/1.1" 304 0
INFO 2019-06-13 06:31:54,277 basehttp 124 "GET /static/images/register_banner.png HTTP/1.1" 304 0
INFO 2019-06-13 06:31:54,279 basehttp 124 "GET /static/images/icons02.png HTTP/1.1" 304 0
INFO 2019-06-13 06:31:54,279 basehttp 124 "GET /static/images/interval_line.png HTTP/1.1" 304 0
INFO 2019-06-13 06:31:58,017 basehttp 124 "GET /mobile/13456789095/count/ HTTP/1.1" 200 23
INFO 2019-06-13 06:32:10,999 basehttp 124 "GET /mobile/13456789095/count/ HTTP/1.1" 200 23
INFO 2019-06-13 06:33:30,125 basehttp 124 "GET /register/ HTTP/1.1" 200 4890
INFO 2019-06-13 06:33:30,154 basehttp 124 "GET /mobile/13456789095/count/ HTTP/1.1" 200 23
INFO 2019-06-13 06:33:30,193 basehttp 124 "GET /static/css/main.css HTTP/1.1" 304 0
INFO 2019-06-13 06:33:30,195 basehttp 124 "GET /static/js/vue-2.5.16.js HTTP/1.1" 304 0
INFO 2019-06-13 06:33:30,196 basehttp 124 "GET /static/css/reset.css HTTP/1.1" 304 0
INFO 2019-06-13 06:33:30,197 basehttp 124 "GET /static/js/axios-0.18.0.min.js HTTP/1.1" 304 0
INFO 2019-06-13 06:33:30,199 basehttp 124 "GET /static/js/common.js HTTP/1.1" 304 0
INFO 2019-06-13 06:33:30,200 basehttp 124 "GET /static/js/host.js HTTP/1.1" 304 0
INFO 2019-06-13 06:33:30,203 basehttp 124 "GET /static/js/register.js HTTP/1.1" 304 0
INFO 2019-06-13 06:33:30,286 basehttp 124 "GET /static/images/logo.png HTTP/1.1" 304 0
INFO 2019-06-13 06:33:30,290 basehttp 124 "GET /static/images/pic_code.jpg HTTP/1.1" 304 0
INFO 2019-06-13 06:33:30,309 basehttp 124 "GET /static/images/interval_line.png HTTP/1.1" 304 0
INFO 2019-06-13 06:33:30,311 basehttp 124 "GET /static/images/register_banner.png HTTP/1.1" 304 0
INFO 2019-06-13 06:33:30,315 basehttp 124 "GET /static/images/icons02.png HTTP/1.1" 304 0
INFO 2019-06-13 06:33:34,372 basehttp 124 "GET /mobile/13456789095/count/ HTTP/1.1" 200 23
INFO 2019-06-13 06:35:03,574 basehttp 124 "GET /register/ HTTP/1.1" 200 4890
INFO 2019-06-13 06:35:03,600 basehttp 124 "GET /mobile/13456789095/count/ HTTP/1.1" 200 23
INFO 2019-06-13 06:35:03,645 basehttp 124 "GET /static/css/main.css HTTP/1.1" 304 0
INFO 2019-06-13 06:35:03,647 basehttp 124 "GET /static/css/reset.css HTTP/1.1" 304 0
INFO 2019-06-13 06:35:03,648 basehttp 124 "GET /static/js/vue-2.5.16.js HTTP/1.1" 304 0
INFO 2019-06-13 06:35:03,650 basehttp 124 "GET /static/js/host.js HTTP/1.1" 304 0
INFO 2019-06-13 06:35:03,658 basehttp 124 "GET /static/js/common.js HTTP/1.1" 304 0
INFO 2019-06-13 06:35:03,659 basehttp 124 "GET /static/js/axios-0.18.0.min.js HTTP/1.1" 304 0
INFO 2019-06-13 06:35:03,661 basehttp 124 "GET /static/js/register.js HTTP/1.1" 200 9068
INFO 2019-06-13 06:35:03,742 basehttp 124 "GET /static/images/logo.png HTTP/1.1" 304 0
INFO 2019-06-13 06:35:03,743 basehttp 124 "GET /static/images/pic_code.jpg HTTP/1.1" 304 0
INFO 2019-06-13 06:35:03,761 basehttp 124 "GET /static/images/interval_line.png HTTP/1.1" 304 0
INFO 2019-06-13 06:35:03,766 basehttp 124 "GET /static/images/register_banner.png HTTP/1.1" 304 0
INFO 2019-06-13 06:35:03,769 basehttp 124 "GET /static/images/icons02.png HTTP/1.1" 304 0
INFO 2019-06-13 06:35:06,682 basehttp 124 "GET /mobile/13456789095/count/ HTTP/1.1" 200 23
WARNING 2019-06-13 08:03:21,184 base 152 Not Found: /
WARNING 2019-06-13 08:03:21,185 basehttp 124 "GET / HTTP/1.1" 404 2714
INFO 2019-06-13 08:03:26,905 basehttp 124 "GET /register/ HTTP/1.1" 200 4890
INFO 2019-06-13 08:03:26,946 basehttp 124 "GET /static/js/register.js HTTP/1.1" 200 9068
INFO 2019-06-13 08:03:31,751 basehttp 124 "GET /usernames/1231231/count/ HTTP/1.1" 200 23
INFO 2019-06-13 08:03:38,301 basehttp 124 "GET /mobile/13456789986/count/ HTTP/1.1" 200 23
WARNING 2019-06-13 09:04:19,884 base 152 Not Found: /image_code/123
WARNING 2019-06-13 09:04:19,885 basehttp 124 "GET /image_code/123 HTTP/1.1" 404 2977
INFO 2019-06-13 09:04:37,356 basehttp 124 "GET /image_codes/123 HTTP/1.1" 301 0
ERROR 2019-06-13 09:04:37,372 exception 135 Internal Server Error: /image_codes/123/
Traceback (most recent call last):
  File "/home/lsy/.virtualenvs/py3_django/lib/python3.5/site-packages/redis/connection.py", line 492, in connect
    sock = self._connect()
  File "/home/lsy/.virtualenvs/py3_django/lib/python3.5/site-packages/redis/connection.py", line 550, in _connect
    raise err
  File "/home/lsy/.virtualenvs/py3_django/lib/python3.5/site-packages/redis/connection.py", line 538, in _connect
    sock.connect(socket_address)
ConnectionRefusedError: [Errno 111] Connection refused

During handling of the above exception, another exception occurred:

Traceback (most recent call last):
  File "/home/lsy/.virtualenvs/py3_django/lib/python3.5/site-packages/django/core/handlers/exception.py", line 41, in inner
    response = get_response(request)
  File "/home/lsy/.virtualenvs/py3_django/lib/python3.5/site-packages/django/core/handlers/base.py", line 187, in _get_response
    response = self.process_exception_by_middleware(e, request)
  File "/home/lsy/.virtualenvs/py3_django/lib/python3.5/site-packages/django/core/handlers/base.py", line 185, in _get_response
    response = wrapped_callback(request, *callback_args, **callback_kwargs)
  File "/home/lsy/.virtualenvs/py3_django/lib/python3.5/site-packages/django/views/generic/base.py", line 68, in view
    return self.dispatch(request, *args, **kwargs)
  File "/home/lsy/.virtualenvs/py3_django/lib/python3.5/site-packages/django/views/generic/base.py", line 88, in dispatch
    return handler(request, *args, **kwargs)
  File "/home/lsy/Desktop/project/meiduo/apps/users/views.py", line 89, in get
    redis_conn.setex(uuid, 240, text)
  File "/home/lsy/.virtualenvs/py3_django/lib/python3.5/site-packages/redis/client.py", line 1472, in setex
    return self.execute_command('SETEX', name, time, value)
  File "/home/lsy/.virtualenvs/py3_django/lib/python3.5/site-packages/redis/client.py", line 772, in execute_command
    connection = pool.get_connection(command_name, **options)
  File "/home/lsy/.virtualenvs/py3_django/lib/python3.5/site-packages/redis/connection.py", line 994, in get_connection
    connection.connect()
  File "/home/lsy/.virtualenvs/py3_django/lib/python3.5/site-packages/redis/connection.py", line 497, in connect
    raise ConnectionError(self._error_message(e))
redis.exceptions.ConnectionError: Error 111 connecting to 127.0.0.1:6379. Connection refused.
ERROR 2019-06-13 09:04:37,418 basehttp 124 "GET /image_codes/123/ HTTP/1.1" 500 118940
ERROR 2019-06-13 09:06:32,110 exception 135 Internal Server Error: /image_codes/123/
Traceback (most recent call last):
  File "/home/lsy/.virtualenvs/py3_django/lib/python3.5/site-packages/redis/connection.py", line 492, in connect
    sock = self._connect()
  File "/home/lsy/.virtualenvs/py3_django/lib/python3.5/site-packages/redis/connection.py", line 550, in _connect
    raise err
  File "/home/lsy/.virtualenvs/py3_django/lib/python3.5/site-packages/redis/connection.py", line 538, in _connect
    sock.connect(socket_address)
ConnectionRefusedError: [Errno 111] Connection refused

During handling of the above exception, another exception occurred:

Traceback (most recent call last):
  File "/home/lsy/.virtualenvs/py3_django/lib/python3.5/site-packages/django/core/handlers/exception.py", line 41, in inner
    response = get_response(request)
  File "/home/lsy/.virtualenvs/py3_django/lib/python3.5/site-packages/django/core/handlers/base.py", line 187, in _get_response
    response = self.process_exception_by_middleware(e, request)
  File "/home/lsy/.virtualenvs/py3_django/lib/python3.5/site-packages/django/core/handlers/base.py", line 185, in _get_response
    response = wrapped_callback(request, *callback_args, **callback_kwargs)
  File "/home/lsy/.virtualenvs/py3_django/lib/python3.5/site-packages/django/views/generic/base.py", line 68, in view
    return self.dispatch(request, *args, **kwargs)
  File "/home/lsy/.virtualenvs/py3_django/lib/python3.5/site-packages/django/views/generic/base.py", line 88, in dispatch
    return handler(request, *args, **kwargs)
  File "/home/lsy/Desktop/project/meiduo/apps/users/views.py", line 89, in get
    redis_conn.setex(uuid, 240, text)
  File "/home/lsy/.virtualenvs/py3_django/lib/python3.5/site-packages/redis/client.py", line 1472, in setex
    return self.execute_command('SETEX', name, time, value)
  File "/home/lsy/.virtualenvs/py3_django/lib/python3.5/site-packages/redis/client.py", line 772, in execute_command
    connection = pool.get_connection(command_name, **options)
  File "/home/lsy/.virtualenvs/py3_django/lib/python3.5/site-packages/redis/connection.py", line 994, in get_connection
    connection.connect()
  File "/home/lsy/.virtualenvs/py3_django/lib/python3.5/site-packages/redis/connection.py", line 497, in connect
    raise ConnectionError(self._error_message(e))
redis.exceptions.ConnectionError: Error 111 connecting to 127.0.0.1:6379. Connection refused.
ERROR 2019-06-13 09:06:32,154 basehttp 124 "GET /image_codes/123/ HTTP/1.1" 500 119058
ERROR 2019-06-13 09:06:32,934 exception 135 Internal Server Error: /image_codes/123/
Traceback (most recent call last):
  File "/home/lsy/.virtualenvs/py3_django/lib/python3.5/site-packages/redis/connection.py", line 492, in connect
    sock = self._connect()
  File "/home/lsy/.virtualenvs/py3_django/lib/python3.5/site-packages/redis/connection.py", line 550, in _connect
    raise err
  File "/home/lsy/.virtualenvs/py3_django/lib/python3.5/site-packages/redis/connection.py", line 538, in _connect
    sock.connect(socket_address)
ConnectionRefusedError: [Errno 111] Connection refused

During handling of the above exception, another exception occurred:

Traceback (most recent call last):
  File "/home/lsy/.virtualenvs/py3_django/lib/python3.5/site-packages/django/core/handlers/exception.py", line 41, in inner
    response = get_response(request)
  File "/home/lsy/.virtualenvs/py3_django/lib/python3.5/site-packages/django/core/handlers/base.py", line 187, in _get_response
    response = self.process_exception_by_middleware(e, request)
  File "/home/lsy/.virtualenvs/py3_django/lib/python3.5/site-packages/django/core/handlers/base.py", line 185, in _get_response
    response = wrapped_callback(request, *callback_args, **callback_kwargs)
  File "/home/lsy/.virtualenvs/py3_django/lib/python3.5/site-packages/django/views/generic/base.py", line 68, in view
    return self.dispatch(request, *args, **kwargs)
  File "/home/lsy/.virtualenvs/py3_django/lib/python3.5/site-packages/django/views/generic/base.py", line 88, in dispatch
    return handler(request, *args, **kwargs)
  File "/home/lsy/Desktop/project/meiduo/apps/users/views.py", line 89, in get
    redis_conn.setex(uuid, 240, text)
  File "/home/lsy/.virtualenvs/py3_django/lib/python3.5/site-packages/redis/client.py", line 1472, in setex
    return self.execute_command('SETEX', name, time, value)
  File "/home/lsy/.virtualenvs/py3_django/lib/python3.5/site-packages/redis/client.py", line 772, in execute_command
    connection = pool.get_connection(command_name, **options)
  File "/home/lsy/.virtualenvs/py3_django/lib/python3.5/site-packages/redis/connection.py", line 994, in get_connection
    connection.connect()
  File "/home/lsy/.virtualenvs/py3_django/lib/python3.5/site-packages/redis/connection.py", line 497, in connect
    raise ConnectionError(self._error_message(e))
redis.exceptions.ConnectionError: Error 111 connecting to 127.0.0.1:6379. Connection refused.
ERROR 2019-06-13 09:06:32,975 basehttp 124 "GET /image_codes/123/ HTTP/1.1" 500 119071
WARNING 2019-06-13 09:06:57,205 base 152 Not Found: /register/image_codes/123
WARNING 2019-06-13 09:06:57,205 basehttp 124 "GET /register/image_codes/123 HTTP/1.1" 404 3007
ERROR 2019-06-13 09:07:15,761 exception 135 Internal Server Error: /image_codes/123/
Traceback (most recent call last):
  File "/home/lsy/.virtualenvs/py3_django/lib/python3.5/site-packages/redis/connection.py", line 492, in connect
    sock = self._connect()
  File "/home/lsy/.virtualenvs/py3_django/lib/python3.5/site-packages/redis/connection.py", line 550, in _connect
    raise err
  File "/home/lsy/.virtualenvs/py3_django/lib/python3.5/site-packages/redis/connection.py", line 538, in _connect
    sock.connect(socket_address)
ConnectionRefusedError: [Errno 111] Connection refused

During handling of the above exception, another exception occurred:

Traceback (most recent call last):
  File "/home/lsy/.virtualenvs/py3_django/lib/python3.5/site-packages/django/core/handlers/exception.py", line 41, in inner
    response = get_response(request)
  File "/home/lsy/.virtualenvs/py3_django/lib/python3.5/site-packages/django/core/handlers/base.py", line 187, in _get_response
    response = self.process_exception_by_middleware(e, request)
  File "/home/lsy/.virtualenvs/py3_django/lib/python3.5/site-packages/django/core/handlers/base.py", line 185, in _get_response
    response = wrapped_callback(request, *callback_args, **callback_kwargs)
  File "/home/lsy/.virtualenvs/py3_django/lib/python3.5/site-packages/django/views/generic/base.py", line 68, in view
    return self.dispatch(request, *args, **kwargs)
  File "/home/lsy/.virtualenvs/py3_django/lib/python3.5/site-packages/django/views/generic/base.py", line 88, in dispatch
    return handler(request, *args, **kwargs)
  File "/home/lsy/Desktop/project/meiduo/apps/users/views.py", line 89, in get
    redis_conn.setex(uuid, 240, text)
  File "/home/lsy/.virtualenvs/py3_django/lib/python3.5/site-packages/redis/client.py", line 1472, in setex
    return self.execute_command('SETEX', name, time, value)
  File "/home/lsy/.virtualenvs/py3_django/lib/python3.5/site-packages/redis/client.py", line 772, in execute_command
    connection = pool.get_connection(command_name, **options)
  File "/home/lsy/.virtualenvs/py3_django/lib/python3.5/site-packages/redis/connection.py", line 994, in get_connection
    connection.connect()
  File "/home/lsy/.virtualenvs/py3_django/lib/python3.5/site-packages/redis/connection.py", line 497, in connect
    raise ConnectionError(self._error_message(e))
redis.exceptions.ConnectionError: Error 111 connecting to 127.0.0.1:6379. Connection refused.
ERROR 2019-06-13 09:07:15,807 basehttp 124 "GET /image_codes/123/ HTTP/1.1" 500 118918
ERROR 2019-06-13 09:07:57,511 exception 135 Internal Server Error: /image_codes/123/
Traceback (most recent call last):
  File "/home/lsy/.virtualenvs/py3_django/lib/python3.5/site-packages/redis/connection.py", line 492, in connect
    sock = self._connect()
  File "/home/lsy/.virtualenvs/py3_django/lib/python3.5/site-packages/redis/connection.py", line 550, in _connect
    raise err
  File "/home/lsy/.virtualenvs/py3_django/lib/python3.5/site-packages/redis/connection.py", line 538, in _connect
    sock.connect(socket_address)
ConnectionRefusedError: [Errno 111] Connection refused

During handling of the above exception, another exception occurred:

Traceback (most recent call last):
  File "/home/lsy/.virtualenvs/py3_django/lib/python3.5/site-packages/django/core/handlers/exception.py", line 41, in inner
    response = get_response(request)
  File "/home/lsy/.virtualenvs/py3_django/lib/python3.5/site-packages/django/core/handlers/base.py", line 187, in _get_response
    response = self.process_exception_by_middleware(e, request)
  File "/home/lsy/.virtualenvs/py3_django/lib/python3.5/site-packages/django/core/handlers/base.py", line 185, in _get_response
    response = wrapped_callback(request, *callback_args, **callback_kwargs)
  File "/home/lsy/.virtualenvs/py3_django/lib/python3.5/site-packages/django/views/generic/base.py", line 68, in view
    return self.dispatch(request, *args, **kwargs)
  File "/home/lsy/.virtualenvs/py3_django/lib/python3.5/site-packages/django/views/generic/base.py", line 88, in dispatch
    return handler(request, *args, **kwargs)
  File "/home/lsy/Desktop/project/meiduo/apps/users/views.py", line 89, in get
    redis_conn.setex(uuid, 240, text)
  File "/home/lsy/.virtualenvs/py3_django/lib/python3.5/site-packages/redis/client.py", line 1472, in setex
    return self.execute_command('SETEX', name, time, value)
  File "/home/lsy/.virtualenvs/py3_django/lib/python3.5/site-packages/redis/client.py", line 772, in execute_command
    connection = pool.get_connection(command_name, **options)
  File "/home/lsy/.virtualenvs/py3_django/lib/python3.5/site-packages/redis/connection.py", line 994, in get_connection
    connection.connect()
  File "/home/lsy/.virtualenvs/py3_django/lib/python3.5/site-packages/redis/connection.py", line 497, in connect
    raise ConnectionError(self._error_message(e))
redis.exceptions.ConnectionError: Error 111 connecting to 127.0.0.1:6379. Connection refused.
ERROR 2019-06-13 09:07:57,555 basehttp 124 "GET /image_codes/123/ HTTP/1.1" 500 119054
ERROR 2019-06-13 09:08:45,305 exception 135 Internal Server Error: /image_codes/12366/
Traceback (most recent call last):
  File "/home/lsy/.virtualenvs/py3_django/lib/python3.5/site-packages/redis/connection.py", line 492, in connect
    sock = self._connect()
  File "/home/lsy/.virtualenvs/py3_django/lib/python3.5/site-packages/redis/connection.py", line 550, in _connect
    raise err
  File "/home/lsy/.virtualenvs/py3_django/lib/python3.5/site-packages/redis/connection.py", line 538, in _connect
    sock.connect(socket_address)
ConnectionRefusedError: [Errno 111] Connection refused

During handling of the above exception, another exception occurred:

Traceback (most recent call last):
  File "/home/lsy/.virtualenvs/py3_django/lib/python3.5/site-packages/django/core/handlers/exception.py", line 41, in inner
    response = get_response(request)
  File "/home/lsy/.virtualenvs/py3_django/lib/python3.5/site-packages/django/core/handlers/base.py", line 187, in _get_response
    response = self.process_exception_by_middleware(e, request)
  File "/home/lsy/.virtualenvs/py3_django/lib/python3.5/site-packages/django/core/handlers/base.py", line 185, in _get_response
    response = wrapped_callback(request, *callback_args, **callback_kwargs)
  File "/home/lsy/.virtualenvs/py3_django/lib/python3.5/site-packages/django/views/generic/base.py", line 68, in view
    return self.dispatch(request, *args, **kwargs)
  File "/home/lsy/.virtualenvs/py3_django/lib/python3.5/site-packages/django/views/generic/base.py", line 88, in dispatch
    return handler(request, *args, **kwargs)
  File "/home/lsy/Desktop/project/meiduo/apps/users/views.py", line 89, in get
    redis_conn.setex(uuid, 240, text)
  File "/home/lsy/.virtualenvs/py3_django/lib/python3.5/site-packages/redis/client.py", line 1472, in setex
    return self.execute_command('SETEX', name, time, value)
  File "/home/lsy/.virtualenvs/py3_django/lib/python3.5/site-packages/redis/client.py", line 772, in execute_command
    connection = pool.get_connection(command_name, **options)
  File "/home/lsy/.virtualenvs/py3_django/lib/python3.5/site-packages/redis/connection.py", line 994, in get_connection
    connection.connect()
  File "/home/lsy/.virtualenvs/py3_django/lib/python3.5/site-packages/redis/connection.py", line 497, in connect
    raise ConnectionError(self._error_message(e))
redis.exceptions.ConnectionError: Error 111 connecting to 127.0.0.1:6379. Connection refused.
ERROR 2019-06-13 09:08:45,352 basehttp 124 "GET /image_codes/12366/ HTTP/1.1" 500 118976
ERROR 2019-06-13 09:10:06,303 exception 135 Internal Server Error: /image_codes/12366/
Traceback (most recent call last):
  File "/home/lsy/.virtualenvs/py3_django/lib/python3.5/site-packages/redis/connection.py", line 492, in connect
    sock = self._connect()
  File "/home/lsy/.virtualenvs/py3_django/lib/python3.5/site-packages/redis/connection.py", line 550, in _connect
    raise err
  File "/home/lsy/.virtualenvs/py3_django/lib/python3.5/site-packages/redis/connection.py", line 538, in _connect
    sock.connect(socket_address)
ConnectionRefusedError: [Errno 111] Connection refused

During handling of the above exception, another exception occurred:

Traceback (most recent call last):
  File "/home/lsy/.virtualenvs/py3_django/lib/python3.5/site-packages/django/core/handlers/exception.py", line 41, in inner
    response = get_response(request)
  File "/home/lsy/.virtualenvs/py3_django/lib/python3.5/site-packages/django/core/handlers/base.py", line 187, in _get_response
    response = self.process_exception_by_middleware(e, request)
  File "/home/lsy/.virtualenvs/py3_django/lib/python3.5/site-packages/django/core/handlers/base.py", line 185, in _get_response
    response = wrapped_callback(request, *callback_args, **callback_kwargs)
  File "/home/lsy/.virtualenvs/py3_django/lib/python3.5/site-packages/django/views/generic/base.py", line 68, in view
    return self.dispatch(request, *args, **kwargs)
  File "/home/lsy/.virtualenvs/py3_django/lib/python3.5/site-packages/django/views/generic/base.py", line 88, in dispatch
    return handler(request, *args, **kwargs)
  File "/home/lsy/Desktop/project/meiduo/apps/users/views.py", line 89, in get
    redis_conn.setex(uuid, 240, text)
  File "/home/lsy/.virtualenvs/py3_django/lib/python3.5/site-packages/redis/client.py", line 1472, in setex
    return self.execute_command('SETEX', name, time, value)
  File "/home/lsy/.virtualenvs/py3_django/lib/python3.5/site-packages/redis/client.py", line 772, in execute_command
    connection = pool.get_connection(command_name, **options)
  File "/home/lsy/.virtualenvs/py3_django/lib/python3.5/site-packages/redis/connection.py", line 994, in get_connection
    connection.connect()
  File "/home/lsy/.virtualenvs/py3_django/lib/python3.5/site-packages/redis/connection.py", line 497, in connect
    raise ConnectionError(self._error_message(e))
redis.exceptions.ConnectionError: Error 111 connecting to 127.0.0.1:6379. Connection refused.
ERROR 2019-06-13 09:10:06,343 basehttp 124 "GET /image_codes/12366/ HTTP/1.1" 500 119107
ERROR 2019-06-13 09:11:11,278 exception 135 Internal Server Error: /image_codes/12366/
Traceback (most recent call last):
  File "/home/lsy/.virtualenvs/py3_django/lib/python3.5/site-packages/redis/connection.py", line 492, in connect
    sock = self._connect()
  File "/home/lsy/.virtualenvs/py3_django/lib/python3.5/site-packages/redis/connection.py", line 550, in _connect
    raise err
  File "/home/lsy/.virtualenvs/py3_django/lib/python3.5/site-packages/redis/connection.py", line 538, in _connect
    sock.connect(socket_address)
ConnectionRefusedError: [Errno 111] Connection refused

During handling of the above exception, another exception occurred:

Traceback (most recent call last):
  File "/home/lsy/.virtualenvs/py3_django/lib/python3.5/site-packages/django/core/handlers/exception.py", line 41, in inner
    response = get_response(request)
  File "/home/lsy/.virtualenvs/py3_django/lib/python3.5/site-packages/django/core/handlers/base.py", line 187, in _get_response
    response = self.process_exception_by_middleware(e, request)
  File "/home/lsy/.virtualenvs/py3_django/lib/python3.5/site-packages/django/core/handlers/base.py", line 185, in _get_response
    response = wrapped_callback(request, *callback_args, **callback_kwargs)
  File "/home/lsy/.virtualenvs/py3_django/lib/python3.5/site-packages/django/views/generic/base.py", line 68, in view
    return self.dispatch(request, *args, **kwargs)
  File "/home/lsy/.virtualenvs/py3_django/lib/python3.5/site-packages/django/views/generic/base.py", line 88, in dispatch
    return handler(request, *args, **kwargs)
  File "/home/lsy/Desktop/project/meiduo/apps/users/views.py", line 89, in get
    redis_conn.setex(uuid, 240, text)
  File "/home/lsy/.virtualenvs/py3_django/lib/python3.5/site-packages/redis/client.py", line 1472, in setex
    return self.execute_command('SETEX', name, time, value)
  File "/home/lsy/.virtualenvs/py3_django/lib/python3.5/site-packages/redis/client.py", line 772, in execute_command
    connection = pool.get_connection(command_name, **options)
  File "/home/lsy/.virtualenvs/py3_django/lib/python3.5/site-packages/redis/connection.py", line 994, in get_connection
    connection.connect()
  File "/home/lsy/.virtualenvs/py3_django/lib/python3.5/site-packages/redis/connection.py", line 497, in connect
    raise ConnectionError(self._error_message(e))
redis.exceptions.ConnectionError: Error 111 connecting to 127.0.0.1:6379. Connection refused.
ERROR 2019-06-13 09:12:03,888 basehttp 124 "GET /image_codes/12366/ HTTP/1.1" 500 121002
ERROR 2019-06-13 09:13:16,807 exception 135 Internal Server Error: /image_codes/12366/
Traceback (most recent call last):
  File "/home/lsy/.virtualenvs/py3_django/lib/python3.5/site-packages/redis/connection.py", line 492, in connect
    sock = self._connect()
  File "/home/lsy/.virtualenvs/py3_django/lib/python3.5/site-packages/redis/connection.py", line 550, in _connect
    raise err
  File "/home/lsy/.virtualenvs/py3_django/lib/python3.5/site-packages/redis/connection.py", line 538, in _connect
    sock.connect(socket_address)
ConnectionRefusedError: [Errno 111] Connection refused

During handling of the above exception, another exception occurred:

Traceback (most recent call last):
  File "/home/lsy/.virtualenvs/py3_django/lib/python3.5/site-packages/django/core/handlers/exception.py", line 41, in inner
    response = get_response(request)
  File "/home/lsy/.virtualenvs/py3_django/lib/python3.5/site-packages/django/core/handlers/base.py", line 187, in _get_response
    response = self.process_exception_by_middleware(e, request)
  File "/home/lsy/.virtualenvs/py3_django/lib/python3.5/site-packages/django/core/handlers/base.py", line 185, in _get_response
    response = wrapped_callback(request, *callback_args, **callback_kwargs)
  File "/home/lsy/.virtualenvs/py3_django/lib/python3.5/site-packages/django/views/generic/base.py", line 68, in view
    return self.dispatch(request, *args, **kwargs)
  File "/home/lsy/.virtualenvs/py3_django/lib/python3.5/site-packages/django/views/generic/base.py", line 88, in dispatch
    return handler(request, *args, **kwargs)
  File "/home/lsy/Desktop/project/meiduo/apps/users/views.py", line 89, in get
    redis_conn.setex(uuid, 240, text)
  File "/home/lsy/.virtualenvs/py3_django/lib/python3.5/site-packages/redis/client.py", line 1472, in setex
    return self.execute_command('SETEX', name, time, value)
  File "/home/lsy/.virtualenvs/py3_django/lib/python3.5/site-packages/redis/client.py", line 772, in execute_command
    connection = pool.get_connection(command_name, **options)
  File "/home/lsy/.virtualenvs/py3_django/lib/python3.5/site-packages/redis/connection.py", line 994, in get_connection
    connection.connect()
  File "/home/lsy/.virtualenvs/py3_django/lib/python3.5/site-packages/redis/connection.py", line 497, in connect
    raise ConnectionError(self._error_message(e))
redis.exceptions.ConnectionError: Error 111 connecting to 127.0.0.1:6379. Connection refused.
ERROR 2019-06-13 09:13:16,960 basehttp 124 "GET /image_codes/12366/ HTTP/1.1" 500 121052
INFO 2019-06-13 09:19:39,882 basehttp 124 "GET /image_codes/12366/ HTTP/1.1" 200 3133
WARNING 2019-06-13 09:19:40,590 base 152 Not Found: /favicon.ico
WARNING 2019-06-13 09:19:40,592 basehttp 124 "GET /favicon.ico HTTP/1.1" 404 2968
INFO 2019-06-13 09:22:02,390 basehttp 124 "GET /register/ HTTP/1.1" 200 4878
INFO 2019-06-13 09:22:02,419 basehttp 124 "GET /static/js/register.js HTTP/1.1" 304 0
ERROR 2019-06-13 09:22:02,481 exception 80 Invalid HTTP_HOST header: 'www.meiduo.site:8000'. You may need to add 'www.meiduo.site' to ALLOWED_HOSTS.
WARNING 2019-06-13 09:22:02,595 basehttp 124 "GET /image_codes/d49c8c63-8475-4d11-940a-289de8af2c4a/ HTTP/1.1" 400 72325
ERROR 2019-06-13 09:22:04,303 exception 80 Invalid HTTP_HOST header: 'www.meiduo.site:8000'. You may need to add 'www.meiduo.site' to ALLOWED_HOSTS.
WARNING 2019-06-13 09:22:04,398 basehttp 124 "GET /image_codes/9af7c5e9-3e84-42ef-b582-8cfbe5724bf1/ HTTP/1.1" 400 72325
ERROR 2019-06-13 09:22:05,316 exception 80 Invalid HTTP_HOST header: 'www.meiduo.site:8000'. You may need to add 'www.meiduo.site' to ALLOWED_HOSTS.
WARNING 2019-06-13 09:22:05,409 basehttp 124 "GET /image_codes/098b1357-d711-49c7-bdd8-7ab0da5c2059/ HTTP/1.1" 400 72325
ERROR 2019-06-13 09:22:14,119 exception 80 Invalid HTTP_HOST header: 'www.meiduo.site:8000'. You may need to add 'www.meiduo.site' to ALLOWED_HOSTS.
WARNING 2019-06-13 09:22:14,217 basehttp 124 "GET /image_codes/f22fa01b-fda1-4577-92de-b6356fc3daff/ HTTP/1.1" 400 72324
ERROR 2019-06-13 09:27:55,458 exception 80 Invalid HTTP_HOST header: 'www.meiduo.site:8000'. You may need to add 'www.meiduo.site' to ALLOWED_HOSTS.
WARNING 2019-06-13 09:27:55,553 basehttp 124 "GET /image_codes/14c7c184-bddf-4f8b-973f-f239bf9c4ef9/ HTTP/1.1" 400 72324
ERROR 2019-06-13 09:30:10,702 exception 80 Invalid HTTP_HOST header: 'www.meiduo.site:8000'. You may need to add 'www.meiduo.site' to ALLOWED_HOSTS.
WARNING 2019-06-13 09:30:10,801 basehttp 124 "GET /image_codes/da00e9f8-42dd-4eff-a807-2c4977284b7f/ HTTP/1.1" 400 72324
INFO 2019-06-13 09:31:02,335 basehttp 124 "GET /image_codes/f22fa01b-fda1-4577-92de-b6356fc3daff/ HTTP/1.1" 200 3469
ERROR 2019-06-13 09:31:34,797 exception 80 Invalid HTTP_HOST header: 'www.meiduo.site:8000'. You may need to add 'www.meiduo.site' to ALLOWED_HOSTS.
WARNING 2019-06-13 09:31:34,906 basehttp 124 "GET /image_codes/244773fd-9a60-47c4-97ba-6e480ed1d048/ HTTP/1.1" 400 72324
ERROR 2019-06-13 09:36:14,933 exception 80 Invalid HTTP_HOST header: 'www.meiduo.site:8000'. You may need to add 'www.meiduo.site' to ALLOWED_HOSTS.
WARNING 2019-06-13 09:36:15,026 basehttp 124 "GET /image_codes/5a9d7b91-8601-464a-b72f-0d1f380e961d/ HTTP/1.1" 400 72324
ERROR 2019-06-13 09:36:45,880 exception 80 Invalid HTTP_HOST header: 'www.meiduo.site:8000'. You may need to add 'www.meiduo.site' to ALLOWED_HOSTS.
WARNING 2019-06-13 09:36:45,987 basehttp 124 "GET /image_codes/5a9d7b91-8601-464a-b72f-0d1f380e961d/ HTTP/1.1" 400 72361
ERROR 2019-06-13 09:36:46,034 exception 80 Invalid HTTP_HOST header: 'www.meiduo.site:8000'. You may need to add 'www.meiduo.site' to ALLOWED_HOSTS.
WARNING 2019-06-13 09:36:46,153 basehttp 124 "GET /favicon.ico HTTP/1.1" 400 71755
ERROR 2019-06-13 09:36:59,647 exception 80 Invalid HTTP_HOST header: 'www.meiduo.site:8000'. You may need to add 'www.meiduo.site' to ALLOWED_HOSTS.
WARNING 2019-06-13 09:36:59,754 basehttp 124 "GET /image_codes/5a9d7b91-8601-464a-b72f-0d1f380e961d/ HTTP/1.1" 400 72496
INFO 2019-06-13 09:39:11,728 basehttp 124 "GET /image_codes/25d2d3db-cf5b-4241-a201-7dcdaa7e4628/ HTTP/1.1" 200 2982
INFO 2019-06-13 09:39:20,068 basehttp 124 "GET /image_codes/93262a21-8117-429a-a6c7-a3425403d391/ HTTP/1.1" 200 3123
INFO 2019-06-13 09:39:26,627 basehttp 124 "GET /image_codes/ddfeddc4-482a-4b6b-b3ec-00c8e4c79b21/ HTTP/1.1" 200 3461
INFO 2019-06-13 09:39:27,155 basehttp 124 "GET /image_codes/f8a9b753-3b51-493d-9fc2-2e950738a57f/ HTTP/1.1" 200 3329
INFO 2019-06-13 09:39:27,671 basehttp 124 "GET /image_codes/3405bd26-3411-4c5d-a273-131d0452edac/ HTTP/1.1" 200 2912
