WARNING 2019-06-12 08:59:59,350 base 152 Not Found: /
WARNING 2019-06-12 08:59:59,350 basehttp 124 "GET / HTTP/1.1" 404 2070
WARNING 2019-06-12 08:59:59,355 base 152 Not Found: /
WARNING 2019-06-12 08:59:59,355 basehttp 124 "GET / HTTP/1.1" 404 2070
WARNING 2019-06-12 08:59:59,442 base 152 Not Found: /favicon.ico
WARNING 2019-06-12 08:59:59,442 basehttp 124 "GET /favicon.ico HTTP/1.1" 404 2121
WARNING 2019-06-12 09:00:08,731 base 152 Not Found: /registration/
WARNING 2019-06-12 09:00:08,732 basehttp 124 "GET /registration/ HTTP/1.1" 404 2127
INFO 2019-06-12 09:00:24,178 basehttp 124 "GET /register HTTP/1.1" 301 0
ERROR 2019-06-12 09:00:24,182 exception 135 Internal Server Error: /register/
Traceback (most recent call last):
  File "/home/lsy/.virtualenvs/py3_django/lib/python3.5/site-packages/django/template/utils.py", line 65, in __getitem__
    return self._engines[alias]
KeyError: 'jinja2'

During handling of the above exception, another exception occurred:

Traceback (most recent call last):
  File "/home/lsy/.virtualenvs/py3_django/lib/python3.5/site-packages/django/core/handlers/exception.py", line 41, in inner
    response = get_response(request)
  File "/home/lsy/.virtualenvs/py3_django/lib/python3.5/site-packages/django/core/handlers/base.py", line 187, in _get_response
    response = self.process_exception_by_middleware(e, request)
  File "/home/lsy/.virtualenvs/py3_django/lib/python3.5/site-packages/django/core/handlers/base.py", line 185, in _get_response
    response = wrapped_callback(request, *callback_args, **callback_kwargs)
  File "/home/lsy/.virtualenvs/py3_django/lib/python3.5/site-packages/django/views/generic/base.py", line 68, in view
    return self.dispatch(request, *args, **kwargs)
  File "/home/lsy/.virtualenvs/py3_django/lib/python3.5/site-packages/django/views/generic/base.py", line 88, in dispatch
    return handler(request, *args, **kwargs)
  File "/home/lsy/Desktop/project/meiduo/apps/users/views.py", line 10, in get
    return render(request, 'register.html')
  File "/home/lsy/.virtualenvs/py3_django/lib/python3.5/site-packages/django/shortcuts.py", line 30, in render
    content = loader.render_to_string(template_name, context, request, using=using)
  File "/home/lsy/.virtualenvs/py3_django/lib/python3.5/site-packages/django/template/loader.py", line 67, in render_to_string
    template = get_template(template_name, using=using)
  File "/home/lsy/.virtualenvs/py3_django/lib/python3.5/site-packages/django/template/loader.py", line 18, in get_template
    engines = _engine_list(using)
  File "/home/lsy/.virtualenvs/py3_django/lib/python3.5/site-packages/django/template/loader.py", line 72, in _engine_list
    return engines.all() if using is None else [engines[using]]
  File "/home/lsy/.virtualenvs/py3_django/lib/python3.5/site-packages/django/template/utils.py", line 89, in all
    return [self[alias] for alias in self]
  File "/home/lsy/.virtualenvs/py3_django/lib/python3.5/site-packages/django/template/utils.py", line 89, in <listcomp>
    return [self[alias] for alias in self]
  File "/home/lsy/.virtualenvs/py3_django/lib/python3.5/site-packages/django/template/utils.py", line 80, in __getitem__
    engine = engine_cls(params)
  File "/home/lsy/.virtualenvs/py3_django/lib/python3.5/site-packages/django/template/backends/jinja2.py", line 29, in __init__
    environment_cls = import_string(environment)
  File "/home/lsy/.virtualenvs/py3_django/lib/python3.5/site-packages/django/utils/module_loading.py", line 20, in import_string
    module = import_module(module_path)
  File "/home/lsy/.virtualenvs/py3_django/lib/python3.5/importlib/__init__.py", line 126, in import_module
    return _bootstrap._gcd_import(name[level:], package, level)
  File "<frozen importlib._bootstrap>", line 986, in _gcd_import
  File "<frozen importlib._bootstrap>", line 969, in _find_and_load
  File "<frozen importlib._bootstrap>", line 956, in _find_and_load_unlocked
ImportError: No module named 'utils.jinja2_env'
ERROR 2019-06-12 09:00:24,231 basehttp 124 "GET /register/ HTTP/1.1" 500 126617
ERROR 2019-06-12 09:00:53,637 exception 135 Internal Server Error: /register/
Traceback (most recent call last):
  File "/home/lsy/.virtualenvs/py3_django/lib/python3.5/site-packages/django/template/utils.py", line 65, in __getitem__
    return self._engines[alias]
KeyError: 'jinja2'

During handling of the above exception, another exception occurred:

Traceback (most recent call last):
  File "/home/lsy/.virtualenvs/py3_django/lib/python3.5/site-packages/django/core/handlers/exception.py", line 41, in inner
    response = get_response(request)
  File "/home/lsy/.virtualenvs/py3_django/lib/python3.5/site-packages/django/core/handlers/base.py", line 187, in _get_response
    response = self.process_exception_by_middleware(e, request)
  File "/home/lsy/.virtualenvs/py3_django/lib/python3.5/site-packages/django/core/handlers/base.py", line 185, in _get_response
    response = wrapped_callback(request, *callback_args, **callback_kwargs)
  File "/home/lsy/.virtualenvs/py3_django/lib/python3.5/site-packages/django/views/generic/base.py", line 68, in view
    return self.dispatch(request, *args, **kwargs)
  File "/home/lsy/.virtualenvs/py3_django/lib/python3.5/site-packages/django/views/generic/base.py", line 88, in dispatch
    return handler(request, *args, **kwargs)
  File "/home/lsy/Desktop/project/meiduo/apps/users/views.py", line 10, in get
    return render(request, 'register.html')
  File "/home/lsy/.virtualenvs/py3_django/lib/python3.5/site-packages/django/shortcuts.py", line 30, in render
    content = loader.render_to_string(template_name, context, request, using=using)
  File "/home/lsy/.virtualenvs/py3_django/lib/python3.5/site-packages/django/template/loader.py", line 67, in render_to_string
    template = get_template(template_name, using=using)
  File "/home/lsy/.virtualenvs/py3_django/lib/python3.5/site-packages/django/template/loader.py", line 18, in get_template
    engines = _engine_list(using)
  File "/home/lsy/.virtualenvs/py3_django/lib/python3.5/site-packages/django/template/loader.py", line 72, in _engine_list
    return engines.all() if using is None else [engines[using]]
  File "/home/lsy/.virtualenvs/py3_django/lib/python3.5/site-packages/django/template/utils.py", line 89, in all
    return [self[alias] for alias in self]
  File "/home/lsy/.virtualenvs/py3_django/lib/python3.5/site-packages/django/template/utils.py", line 89, in <listcomp>
    return [self[alias] for alias in self]
  File "/home/lsy/.virtualenvs/py3_django/lib/python3.5/site-packages/django/template/utils.py", line 80, in __getitem__
    engine = engine_cls(params)
  File "/home/lsy/.virtualenvs/py3_django/lib/python3.5/site-packages/django/template/backends/jinja2.py", line 29, in __init__
    environment_cls = import_string(environment)
  File "/home/lsy/.virtualenvs/py3_django/lib/python3.5/site-packages/django/utils/module_loading.py", line 20, in import_string
    module = import_module(module_path)
  File "/home/lsy/.virtualenvs/py3_django/lib/python3.5/importlib/__init__.py", line 126, in import_module
    return _bootstrap._gcd_import(name[level:], package, level)
  File "<frozen importlib._bootstrap>", line 986, in _gcd_import
  File "<frozen importlib._bootstrap>", line 969, in _find_and_load
  File "<frozen importlib._bootstrap>", line 956, in _find_and_load_unlocked
ImportError: No module named 'utils.jinja2_env'
ERROR 2019-06-12 09:00:53,683 basehttp 124 "GET /register/ HTTP/1.1" 500 126752
ERROR 2019-06-12 09:00:55,586 exception 135 Internal Server Error: /register/
Traceback (most recent call last):
  File "/home/lsy/.virtualenvs/py3_django/lib/python3.5/site-packages/django/template/utils.py", line 65, in __getitem__
    return self._engines[alias]
KeyError: 'jinja2'

During handling of the above exception, another exception occurred:

Traceback (most recent call last):
  File "/home/lsy/.virtualenvs/py3_django/lib/python3.5/site-packages/django/core/handlers/exception.py", line 41, in inner
    response = get_response(request)
  File "/home/lsy/.virtualenvs/py3_django/lib/python3.5/site-packages/django/core/handlers/base.py", line 187, in _get_response
    response = self.process_exception_by_middleware(e, request)
  File "/home/lsy/.virtualenvs/py3_django/lib/python3.5/site-packages/django/core/handlers/base.py", line 185, in _get_response
    response = wrapped_callback(request, *callback_args, **callback_kwargs)
  File "/home/lsy/.virtualenvs/py3_django/lib/python3.5/site-packages/django/views/generic/base.py", line 68, in view
    return self.dispatch(request, *args, **kwargs)
  File "/home/lsy/.virtualenvs/py3_django/lib/python3.5/site-packages/django/views/generic/base.py", line 88, in dispatch
    return handler(request, *args, **kwargs)
  File "/home/lsy/Desktop/project/meiduo/apps/users/views.py", line 10, in get
    return render(request, 'register.html')
  File "/home/lsy/.virtualenvs/py3_django/lib/python3.5/site-packages/django/shortcuts.py", line 30, in render
    content = loader.render_to_string(template_name, context, request, using=using)
  File "/home/lsy/.virtualenvs/py3_django/lib/python3.5/site-packages/django/template/loader.py", line 67, in render_to_string
    template = get_template(template_name, using=using)
  File "/home/lsy/.virtualenvs/py3_django/lib/python3.5/site-packages/django/template/loader.py", line 18, in get_template
    engines = _engine_list(using)
  File "/home/lsy/.virtualenvs/py3_django/lib/python3.5/site-packages/django/template/loader.py", line 72, in _engine_list
    return engines.all() if using is None else [engines[using]]
  File "/home/lsy/.virtualenvs/py3_django/lib/python3.5/site-packages/django/template/utils.py", line 89, in all
    return [self[alias] for alias in self]
  File "/home/lsy/.virtualenvs/py3_django/lib/python3.5/site-packages/django/template/utils.py", line 89, in <listcomp>
    return [self[alias] for alias in self]
  File "/home/lsy/.virtualenvs/py3_django/lib/python3.5/site-packages/django/template/utils.py", line 80, in __getitem__
    engine = engine_cls(params)
  File "/home/lsy/.virtualenvs/py3_django/lib/python3.5/site-packages/django/template/backends/jinja2.py", line 29, in __init__
    environment_cls = import_string(environment)
  File "/home/lsy/.virtualenvs/py3_django/lib/python3.5/site-packages/django/utils/module_loading.py", line 20, in import_string
    module = import_module(module_path)
  File "/home/lsy/.virtualenvs/py3_django/lib/python3.5/importlib/__init__.py", line 126, in import_module
    return _bootstrap._gcd_import(name[level:], package, level)
  File "<frozen importlib._bootstrap>", line 986, in _gcd_import
  File "<frozen importlib._bootstrap>", line 969, in _find_and_load
  File "<frozen importlib._bootstrap>", line 956, in _find_and_load_unlocked
ImportError: No module named 'utils.jinja2_env'
ERROR 2019-06-12 09:00:55,630 basehttp 124 "GET /register/ HTTP/1.1" 500 126752
ERROR 2019-06-12 09:01:49,672 exception 135 Internal Server Error: /register/
Traceback (most recent call last):
  File "/home/lsy/.virtualenvs/py3_django/lib/python3.5/site-packages/django/template/utils.py", line 65, in __getitem__
    return self._engines[alias]
KeyError: 'jinja2'

During handling of the above exception, another exception occurred:

Traceback (most recent call last):
  File "/home/lsy/.virtualenvs/py3_django/lib/python3.5/site-packages/django/core/handlers/exception.py", line 41, in inner
    response = get_response(request)
  File "/home/lsy/.virtualenvs/py3_django/lib/python3.5/site-packages/django/core/handlers/base.py", line 187, in _get_response
    response = self.process_exception_by_middleware(e, request)
  File "/home/lsy/.virtualenvs/py3_django/lib/python3.5/site-packages/django/core/handlers/base.py", line 185, in _get_response
    response = wrapped_callback(request, *callback_args, **callback_kwargs)
  File "/home/lsy/.virtualenvs/py3_django/lib/python3.5/site-packages/django/views/generic/base.py", line 68, in view
    return self.dispatch(request, *args, **kwargs)
  File "/home/lsy/.virtualenvs/py3_django/lib/python3.5/site-packages/django/views/generic/base.py", line 88, in dispatch
    return handler(request, *args, **kwargs)
  File "/home/lsy/Desktop/project/meiduo/apps/users/views.py", line 10, in get
    return render(request, 'register.html')
  File "/home/lsy/.virtualenvs/py3_django/lib/python3.5/site-packages/django/shortcuts.py", line 30, in render
    content = loader.render_to_string(template_name, context, request, using=using)
  File "/home/lsy/.virtualenvs/py3_django/lib/python3.5/site-packages/django/template/loader.py", line 67, in render_to_string
    template = get_template(template_name, using=using)
  File "/home/lsy/.virtualenvs/py3_django/lib/python3.5/site-packages/django/template/loader.py", line 18, in get_template
    engines = _engine_list(using)
  File "/home/lsy/.virtualenvs/py3_django/lib/python3.5/site-packages/django/template/loader.py", line 72, in _engine_list
    return engines.all() if using is None else [engines[using]]
  File "/home/lsy/.virtualenvs/py3_django/lib/python3.5/site-packages/django/template/utils.py", line 89, in all
    return [self[alias] for alias in self]
  File "/home/lsy/.virtualenvs/py3_django/lib/python3.5/site-packages/django/template/utils.py", line 89, in <listcomp>
    return [self[alias] for alias in self]
  File "/home/lsy/.virtualenvs/py3_django/lib/python3.5/site-packages/django/template/utils.py", line 80, in __getitem__
    engine = engine_cls(params)
  File "/home/lsy/.virtualenvs/py3_django/lib/python3.5/site-packages/django/template/backends/jinja2.py", line 29, in __init__
    environment_cls = import_string(environment)
  File "/home/lsy/.virtualenvs/py3_django/lib/python3.5/site-packages/django/utils/module_loading.py", line 20, in import_string
    module = import_module(module_path)
  File "/home/lsy/.virtualenvs/py3_django/lib/python3.5/importlib/__init__.py", line 126, in import_module
    return _bootstrap._gcd_import(name[level:], package, level)
  File "<frozen importlib._bootstrap>", line 986, in _gcd_import
  File "<frozen importlib._bootstrap>", line 969, in _find_and_load
  File "<frozen importlib._bootstrap>", line 956, in _find_and_load_unlocked
ImportError: No module named 'utils.jinja2_env'
ERROR 2019-06-12 09:01:49,716 basehttp 124 "GET /register/ HTTP/1.1" 500 126752
ERROR 2019-06-12 09:01:50,768 exception 135 Internal Server Error: /register/
Traceback (most recent call last):
  File "/home/lsy/.virtualenvs/py3_django/lib/python3.5/site-packages/django/template/utils.py", line 65, in __getitem__
    return self._engines[alias]
KeyError: 'jinja2'

During handling of the above exception, another exception occurred:

Traceback (most recent call last):
  File "/home/lsy/.virtualenvs/py3_django/lib/python3.5/site-packages/django/core/handlers/exception.py", line 41, in inner
    response = get_response(request)
  File "/home/lsy/.virtualenvs/py3_django/lib/python3.5/site-packages/django/core/handlers/base.py", line 187, in _get_response
    response = self.process_exception_by_middleware(e, request)
  File "/home/lsy/.virtualenvs/py3_django/lib/python3.5/site-packages/django/core/handlers/base.py", line 185, in _get_response
    response = wrapped_callback(request, *callback_args, **callback_kwargs)
  File "/home/lsy/.virtualenvs/py3_django/lib/python3.5/site-packages/django/views/generic/base.py", line 68, in view
    return self.dispatch(request, *args, **kwargs)
  File "/home/lsy/.virtualenvs/py3_django/lib/python3.5/site-packages/django/views/generic/base.py", line 88, in dispatch
    return handler(request, *args, **kwargs)
  File "/home/lsy/Desktop/project/meiduo/apps/users/views.py", line 10, in get
    return render(request, 'register.html')
  File "/home/lsy/.virtualenvs/py3_django/lib/python3.5/site-packages/django/shortcuts.py", line 30, in render
    content = loader.render_to_string(template_name, context, request, using=using)
  File "/home/lsy/.virtualenvs/py3_django/lib/python3.5/site-packages/django/template/loader.py", line 67, in render_to_string
    template = get_template(template_name, using=using)
  File "/home/lsy/.virtualenvs/py3_django/lib/python3.5/site-packages/django/template/loader.py", line 18, in get_template
    engines = _engine_list(using)
  File "/home/lsy/.virtualenvs/py3_django/lib/python3.5/site-packages/django/template/loader.py", line 72, in _engine_list
    return engines.all() if using is None else [engines[using]]
  File "/home/lsy/.virtualenvs/py3_django/lib/python3.5/site-packages/django/template/utils.py", line 89, in all
    return [self[alias] for alias in self]
  File "/home/lsy/.virtualenvs/py3_django/lib/python3.5/site-packages/django/template/utils.py", line 89, in <listcomp>
    return [self[alias] for alias in self]
  File "/home/lsy/.virtualenvs/py3_django/lib/python3.5/site-packages/django/template/utils.py", line 80, in __getitem__
    engine = engine_cls(params)
  File "/home/lsy/.virtualenvs/py3_django/lib/python3.5/site-packages/django/template/backends/jinja2.py", line 29, in __init__
    environment_cls = import_string(environment)
  File "/home/lsy/.virtualenvs/py3_django/lib/python3.5/site-packages/django/utils/module_loading.py", line 20, in import_string
    module = import_module(module_path)
  File "/home/lsy/.virtualenvs/py3_django/lib/python3.5/importlib/__init__.py", line 126, in import_module
    return _bootstrap._gcd_import(name[level:], package, level)
  File "<frozen importlib._bootstrap>", line 986, in _gcd_import
  File "<frozen importlib._bootstrap>", line 969, in _find_and_load
  File "<frozen importlib._bootstrap>", line 956, in _find_and_load_unlocked
ImportError: No module named 'utils.jinja2_env'
ERROR 2019-06-12 09:01:50,813 basehttp 124 "GET /register/ HTTP/1.1" 500 126752
ERROR 2019-06-12 09:01:51,902 exception 135 Internal Server Error: /register/
Traceback (most recent call last):
  File "/home/lsy/.virtualenvs/py3_django/lib/python3.5/site-packages/django/template/utils.py", line 65, in __getitem__
    return self._engines[alias]
KeyError: 'jinja2'

During handling of the above exception, another exception occurred:

Traceback (most recent call last):
  File "/home/lsy/.virtualenvs/py3_django/lib/python3.5/site-packages/django/core/handlers/exception.py", line 41, in inner
    response = get_response(request)
  File "/home/lsy/.virtualenvs/py3_django/lib/python3.5/site-packages/django/core/handlers/base.py", line 187, in _get_response
    response = self.process_exception_by_middleware(e, request)
  File "/home/lsy/.virtualenvs/py3_django/lib/python3.5/site-packages/django/core/handlers/base.py", line 185, in _get_response
    response = wrapped_callback(request, *callback_args, **callback_kwargs)
  File "/home/lsy/.virtualenvs/py3_django/lib/python3.5/site-packages/django/views/generic/base.py", line 68, in view
    return self.dispatch(request, *args, **kwargs)
  File "/home/lsy/.virtualenvs/py3_django/lib/python3.5/site-packages/django/views/generic/base.py", line 88, in dispatch
    return handler(request, *args, **kwargs)
  File "/home/lsy/Desktop/project/meiduo/apps/users/views.py", line 10, in get
    return render(request, 'register.html')
  File "/home/lsy/.virtualenvs/py3_django/lib/python3.5/site-packages/django/shortcuts.py", line 30, in render
    content = loader.render_to_string(template_name, context, request, using=using)
  File "/home/lsy/.virtualenvs/py3_django/lib/python3.5/site-packages/django/template/loader.py", line 67, in render_to_string
    template = get_template(template_name, using=using)
  File "/home/lsy/.virtualenvs/py3_django/lib/python3.5/site-packages/django/template/loader.py", line 18, in get_template
    engines = _engine_list(using)
  File "/home/lsy/.virtualenvs/py3_django/lib/python3.5/site-packages/django/template/loader.py", line 72, in _engine_list
    return engines.all() if using is None else [engines[using]]
  File "/home/lsy/.virtualenvs/py3_django/lib/python3.5/site-packages/django/template/utils.py", line 89, in all
    return [self[alias] for alias in self]
  File "/home/lsy/.virtualenvs/py3_django/lib/python3.5/site-packages/django/template/utils.py", line 89, in <listcomp>
    return [self[alias] for alias in self]
  File "/home/lsy/.virtualenvs/py3_django/lib/python3.5/site-packages/django/template/utils.py", line 80, in __getitem__
    engine = engine_cls(params)
  File "/home/lsy/.virtualenvs/py3_django/lib/python3.5/site-packages/django/template/backends/jinja2.py", line 29, in __init__
    environment_cls = import_string(environment)
  File "/home/lsy/.virtualenvs/py3_django/lib/python3.5/site-packages/django/utils/module_loading.py", line 20, in import_string
    module = import_module(module_path)
  File "/home/lsy/.virtualenvs/py3_django/lib/python3.5/importlib/__init__.py", line 126, in import_module
    return _bootstrap._gcd_import(name[level:], package, level)
  File "<frozen importlib._bootstrap>", line 986, in _gcd_import
  File "<frozen importlib._bootstrap>", line 969, in _find_and_load
  File "<frozen importlib._bootstrap>", line 956, in _find_and_load_unlocked
ImportError: No module named 'utils.jinja2_env'
ERROR 2019-06-12 09:01:51,945 basehttp 124 "GET /register/ HTTP/1.1" 500 126752
ERROR 2019-06-12 09:05:26,739 exception 135 Internal Server Error: /register/
Traceback (most recent call last):
  File "/home/lsy/.virtualenvs/py3_django/lib/python3.5/site-packages/django/template/utils.py", line 65, in __getitem__
    return self._engines[alias]
KeyError: 'jinja2'

During handling of the above exception, another exception occurred:

Traceback (most recent call last):
  File "/home/lsy/.virtualenvs/py3_django/lib/python3.5/site-packages/django/core/handlers/exception.py", line 41, in inner
    response = get_response(request)
  File "/home/lsy/.virtualenvs/py3_django/lib/python3.5/site-packages/django/core/handlers/base.py", line 187, in _get_response
    response = self.process_exception_by_middleware(e, request)
  File "/home/lsy/.virtualenvs/py3_django/lib/python3.5/site-packages/django/core/handlers/base.py", line 185, in _get_response
    response = wrapped_callback(request, *callback_args, **callback_kwargs)
  File "/home/lsy/.virtualenvs/py3_django/lib/python3.5/site-packages/django/views/generic/base.py", line 68, in view
    return self.dispatch(request, *args, **kwargs)
  File "/home/lsy/.virtualenvs/py3_django/lib/python3.5/site-packages/django/views/generic/base.py", line 88, in dispatch
    return handler(request, *args, **kwargs)
  File "/home/lsy/Desktop/project/meiduo/apps/users/views.py", line 10, in get
    return render(request, 'register.html')
  File "/home/lsy/.virtualenvs/py3_django/lib/python3.5/site-packages/django/shortcuts.py", line 30, in render
    content = loader.render_to_string(template_name, context, request, using=using)
  File "/home/lsy/.virtualenvs/py3_django/lib/python3.5/site-packages/django/template/loader.py", line 67, in render_to_string
    template = get_template(template_name, using=using)
  File "/home/lsy/.virtualenvs/py3_django/lib/python3.5/site-packages/django/template/loader.py", line 18, in get_template
    engines = _engine_list(using)
  File "/home/lsy/.virtualenvs/py3_django/lib/python3.5/site-packages/django/template/loader.py", line 72, in _engine_list
    return engines.all() if using is None else [engines[using]]
  File "/home/lsy/.virtualenvs/py3_django/lib/python3.5/site-packages/django/template/utils.py", line 89, in all
    return [self[alias] for alias in self]
  File "/home/lsy/.virtualenvs/py3_django/lib/python3.5/site-packages/django/template/utils.py", line 89, in <listcomp>
    return [self[alias] for alias in self]
  File "/home/lsy/.virtualenvs/py3_django/lib/python3.5/site-packages/django/template/utils.py", line 80, in __getitem__
    engine = engine_cls(params)
  File "/home/lsy/.virtualenvs/py3_django/lib/python3.5/site-packages/django/template/backends/jinja2.py", line 29, in __init__
    environment_cls = import_string(environment)
  File "/home/lsy/.virtualenvs/py3_django/lib/python3.5/site-packages/django/utils/module_loading.py", line 20, in import_string
    module = import_module(module_path)
  File "/home/lsy/.virtualenvs/py3_django/lib/python3.5/importlib/__init__.py", line 126, in import_module
    return _bootstrap._gcd_import(name[level:], package, level)
  File "<frozen importlib._bootstrap>", line 986, in _gcd_import
  File "<frozen importlib._bootstrap>", line 969, in _find_and_load
  File "<frozen importlib._bootstrap>", line 944, in _find_and_load_unlocked
  File "<frozen importlib._bootstrap>", line 222, in _call_with_frames_removed
  File "<frozen importlib._bootstrap>", line 986, in _gcd_import
  File "<frozen importlib._bootstrap>", line 969, in _find_and_load
  File "<frozen importlib._bootstrap>", line 956, in _find_and_load_unlocked
ImportError: No module named 'utils'
ERROR 2019-06-12 09:05:26,793 basehttp 124 "GET /register/ HTTP/1.1" 500 126708
INFO 2019-06-12 09:07:56,765 basehttp 124 "GET /register/ HTTP/1.1" 200 4891
INFO 2019-06-12 09:07:56,782 basehttp 124 "GET /static/js/axios-0.18.0.min.js HTTP/1.1" 200 12941
INFO 2019-06-12 09:07:56,783 basehttp 124 "GET /static/css/reset.css HTTP/1.1" 304 0
INFO 2019-06-12 09:07:56,787 basehttp 124 "GET /static/images/logo.png HTTP/1.1" 304 0
INFO 2019-06-12 09:07:56,788 basehttp 124 "GET /static/css/main.css HTTP/1.1" 304 0
INFO 2019-06-12 09:07:56,790 basehttp 124 "GET /static/images/pic_code.jpg HTTP/1.1" 304 0
INFO 2019-06-12 09:07:56,791 basehttp 124 "GET /static/js/vue-2.5.16.js HTTP/1.1" 200 289307
INFO 2019-06-12 09:07:56,796 basehttp 124 "GET /static/js/host.js HTTP/1.1" 304 0
INFO 2019-06-12 09:07:56,801 basehttp 124 "GET /static/js/common.js HTTP/1.1" 304 0
INFO 2019-06-12 09:07:56,807 basehttp 124 "GET /static/js/register.js HTTP/1.1" 304 0
INFO 2019-06-12 09:07:56,814 basehttp 124 "GET /static/images/interval_line.png HTTP/1.1" 304 0
INFO 2019-06-12 09:07:56,817 basehttp 124 "GET /static/images/register_banner.png HTTP/1.1" 304 0
INFO 2019-06-12 09:07:56,818 basehttp 124 "GET /static/images/icons02.png HTTP/1.1" 304 0
